<?xml version="1.0" encoding="utf-8"?>
<robot name="4C2">
  <link
    name="base_link">
    <inertial>
      <origin
        xyz="-0.00025 0.0005200000000000001 0.04618"
        rpy="0 0 0" />
      <mass
        value="0.17456" />
      <inertia
        ixx="0.00017385082"
        ixy="-7.1123e-07"
        ixz="1.59872e-06"
        iyy="0.00014821157"
        iyz="-5.41808e-06"
        izz="4.7929489999999995e-05" />
    </inertial>
    <visual>
      <origin
        xyz="0 0 0"
        rpy="0 0 0" />
      <geometry>
        <mesh
          filename="package://4C2/meshes/base_link.STL" />
      </geometry>
      <material
        name="">
        <color
          rgba="0.25 0.25 0.25 1" />
      </material>
    </visual>
    <collision>
      <origin
        xyz="0 0 0"
        rpy="0 0 0" />
      <geometry>
        <mesh
          filename="package://4C2/meshes/base_link.STL" />
      </geometry>
    </collision>
  </link>
  <link
    name="r_1">
    <inertial>
      <origin
        xyz="0.015880000000000002 0.00512 0.01252"
        rpy="0 0 0" />
      <mass
        value="0.00864" />
      <inertia
        ixx="6.1597e-07"
        ixy="-6.8471e-07"
        ixz="2.8500000000000003e-09"
        iyy="2.5165100000000002e-06"
        iyz="9.2e-10"
        izz="2.3915300000000003e-06" />
    </inertial>
    <visual>
      <origin
        xyz="0 0 0"
        rpy="0 0 0" />
      <geometry>
        <mesh
          filename="package://4C2/meshes/r_1.STL" />
      </geometry>
      <material
        name="">
        <color
          rgba="0.25 0.25 0.25 1" />
      </material>
    </visual>
    <collision>
      <origin
        xyz="0 0 0"
        rpy="0 0 0" />
      <geometry>
        <mesh
          filename="package://4C2/meshes/r_1.STL" />
      </geometry>
    </collision>
  </link>
  <joint
    name="gripper_joint"
    type="revolute">
    <origin
      xyz="-0.0125 0.04 0.079"
      rpy="3.1416 -1.5708 0" />
    <parent
      link="base_link" />
    <child
      link="r_1" />
    <axis
      xyz="0 0 1" />
    <limit
      lower="0"
      upper="0.865"
      effort="1"
      velocity="2" />
  </joint>
  <link
    name="r_3">
    <inertial>
      <origin
        xyz="0.00894 -0.01025 0.009"
        rpy="0 0 0" />
      <mass
        value="0.00967" />
      <inertia
        ixx="4.7741e-07"
        ixy="2.7354e-07"
        ixz="-0.0"
        iyy="1.01048e-06"
        iyz="-0.0"
        izz="1.13484e-06" />
    </inertial>
    <visual>
      <origin
        xyz="0 0 0"
        rpy="0 0 0" />
      <geometry>
        <mesh
          filename="package://4C2/meshes/r_3.STL" />
      </geometry>
      <material
        name="">
        <color
          rgba="0.4 0.4 0.4 1" />
      </material>
    </visual>
    <collision>
      <origin
        xyz="0 0 0"
        rpy="0 0 0" />
      <geometry>
        <mesh
          filename="package://4C2/meshes/r_3.STL" />
      </geometry>
    </collision>
  </link>
  <joint
    name="r_3_joint"
    type="revolute">
    <origin
      xyz="0.03997 -0.0129 0.0035"
      rpy="0 0 0" />
    <parent
      link="r_1" />
    <child
      link="r_3" />
    <axis
      xyz="0 0 -1" />
    <limit
      lower="0"
      upper="1"
      effort="1"
      velocity="2" />
    <mimic
        joint="gripper_joint"
        multiplier="1"
        offset="0" />
  </joint>
  <link
    name="l_1">
    <inertial>
      <origin
        xyz="0.015880000000000002 -0.00512 0.01249"
        rpy="0 0 0" />
      <mass
        value="0.00864" />
      <inertia
        ixx="6.1597e-07"
        ixy="6.8471e-07"
        ixz="-8.4e-10"
        iyy="2.5165100000000002e-06"
        iyz="2.7e-10"
        izz="2.3915300000000003e-06" />
    </inertial>
    <visual>
      <origin
        xyz="0 0 0"
        rpy="0 0 0" />
      <geometry>
        <mesh
          filename="package://4C2/meshes/l_1.STL" />
      </geometry>
      <material
        name="">
        <color
          rgba="0.25 0.25 0.25 1" />
      </material>
    </visual>
    <collision>
      <origin
        xyz="0 0 0"
        rpy="0 0 0" />
      <geometry>
        <mesh
          filename="package://4C2/meshes/l_1.STL" />
      </geometry>
    </collision>
  </link>
  <joint
    name="l_1_joint"
    type="revolute">
    <origin
      xyz="-0.0125 -0.04 0.079"
      rpy="3.1416 -1.5708 0" />
    <parent
      link="base_link" />
    <child
      link="l_1" />
    <axis
      xyz="0 0 -1" />
    <limit
      lower="0"
      upper="1"
      effort="1"
      velocity="2" />
    <mimic
        joint="gripper_joint"
        multiplier="1"
        offset="0" />
  </joint>
  <link
    name="l_3">
    <inertial>
      <origin
        xyz="0.00894 0.01025 0.009"
        rpy="0 0 0" />
      <mass
        value="0.00967" />
      <inertia
        ixx="4.7741e-07"
        ixy="-2.7354e-07"
        ixz="-0.0"
        iyy="1.01048e-06"
        iyz="-0.0"
        izz="1.13484e-06" />
    </inertial>
    <visual>
      <origin
        xyz="0 0 0"
        rpy="0 0 0" />
      <geometry>
        <mesh
          filename="package://4C2/meshes/l_3.STL" />
      </geometry>
      <material
        name="">
        <color
          rgba="0.4 0.4 0.4 1" />
      </material>
    </visual>
    <collision>
      <origin
        xyz="0 0 0"
        rpy="0 0 0" />
      <geometry>
        <mesh
          filename="package://4C2/meshes/l_3.STL" />
      </geometry>
    </collision>
  </link>
  <joint
    name="l_3_joint"
    type="revolute">
    <origin
      xyz="0.03997 0.0129 0.0035"
      rpy="0 0 0" />
    <parent
      link="l_1" />
    <child
      link="l_3" />
    <axis
      xyz="0 0 1" />
    <limit
      lower="0"
      upper="1"
      effort="1"
      velocity="2" />
    <mimic
        joint="gripper_joint"
        multiplier="1"
        offset="0" />
  </joint>
  <link
    name="r_2_base">
    <inertial>
      <origin
        xyz="1.80411241501588E-16 -1.38777878078145E-17 0.0124577241215472"
        rpy="0 0 0" />
      <mass
        value="0.000523674592701008" />
      <inertia
        ixx="3.07347148157248E-08"
        ixy="2.19812746469581E-26"
        ixz="-1.61003603633463E-23"
        iyy="3.07347148157248E-08"
        iyz="-1.75942006429497E-23"
        izz="7.12500693959128E-10" />
    </inertial>
    <visual>
      <origin
        xyz="0 0 0"
        rpy="0 0 0" />
      <geometry>
        <mesh
          filename="package://4C2/meshes/r_2_base.STL" />
      </geometry>
      <material
        name="">
        <color
          rgba="0.898039215686275 0.917647058823529 0.929411764705882 1" />
      </material>
    </visual>
    <collision>
      <origin
        xyz="0 0 0"
        rpy="0 0 0" />
      <geometry>
        <mesh
          filename="package://4C2/meshes/r_2_base.STL" />
      </geometry>
    </collision>
  </link>
  <joint
    name="r_2_base_joint"
    type="fixed">
    <origin
      xyz="-0.0125 0.03 0.081"
      rpy="3.1416 -1.5708 0" />
    <parent
      link="base_link" />
    <child
      link="r_2_base" />
    <axis
      xyz="0 0 1" />
  </joint>
  <link
    name="r_2">
    <inertial>
      <origin
        xyz="0.01758 0.005679999999999999 0.01248"
        rpy="0 0 0" />
      <mass
        value="0.01199" />
      <inertia
        ixx="6.1843e-07"
        ixy="-6.0251e-07"
        ixz="-1.99e-09"
        iyy="2.2908200000000003e-06"
        iyz="-6.400000000000001e-10"
        izz="2.13501e-06" />
    </inertial>
    <visual>
      <origin
        xyz="0 0 0"
        rpy="0 0 0" />
      <geometry>
        <mesh
          filename="package://4C2/meshes/r_2.STL" />
      </geometry>
      <material
        name="">
        <color
          rgba="0.25 0.25 0.25 1" />
      </material>
    </visual>
    <collision>
      <origin
        xyz="0 0 0"
        rpy="0 0 0" />
      <geometry>
        <mesh
          filename="package://4C2/meshes/r_2.STL" />
      </geometry>
    </collision>
  </link>
  <joint
    name="r_2_joint"
    type="revolute">
    <origin
      xyz="0 0 0"
      rpy="0 0 0" />
    <parent
      link="r_2_base" />
    <child
      link="r_2" />
    <axis
      xyz="0 0 1" />
    <limit
      lower="0"
      upper="1"
      effort="1"
      velocity="2" />
    <mimic
        joint="gripper_joint"
        multiplier="1"
        offset="0" />
  </joint>
  <link
    name="l_2_base">
    <inertial>
      <origin
        xyz="4.9960036108132E-16 6.48786580015326E-16 0.012531825941704"
        rpy="0 0 0" />
      <mass
        value="0.000523674592701011" />
      <inertia
        ixx="3.0734714815725E-08"
        ixy="-3.98073805558355E-27"
        ixz="-1.82481294203138E-23"
        iyy="3.0734714815725E-08"
        iyz="1.84719820823576E-24"
        izz="7.12500693959128E-10" />
    </inertial>
    <visual>
      <origin
        xyz="0 0 0"
        rpy="0 0 0" />
      <geometry>
        <mesh
          filename="package://4C2/meshes/l_2_base.STL" />
      </geometry>
      <material
        name="">
        <color
          rgba="0.898039215686275 0.917647058823529 0.929411764705882 1" />
      </material>
    </visual>
    <collision>
      <origin
        xyz="0 0 0"
        rpy="0 0 0" />
      <geometry>
        <mesh
          filename="package://4C2/meshes/l_2_base.STL" />
      </geometry>
    </collision>
  </link>
  <joint
    name="l_2_base_joint"
    type="fixed">
    <origin
      xyz="-0.012574 -0.03 0.081"
      rpy="3.1416 -1.5708 0" />
    <parent
      link="base_link" />
    <child
      link="l_2_base" />
    <axis
      xyz="0 0 1" />
  </joint>
  <link
    name="l_2">
    <inertial>
      <origin
        xyz="0.01758 -0.005679999999999999 0.01252"
        rpy="0 0 0" />
      <mass
        value="0.01199" />
      <inertia
        ixx="6.1843e-07"
        ixy="6.0251e-07"
        ixz="1.99e-09"
        iyy="2.2908200000000003e-06"
        iyz="-6.400000000000001e-10"
        izz="2.13501e-06" />
    </inertial>
    <visual>
      <origin
        xyz="0 0 0"
        rpy="0 0 0" />
      <geometry>
        <mesh
          filename="package://4C2/meshes/l_2.STL" />
      </geometry>
      <material
        name="">
        <color
          rgba="0.25 0.25 0.25 1" />
      </material>
    </visual>
    <collision>
      <origin
        xyz="0 0 0"
        rpy="0 0 0" />
      <geometry>
        <mesh
          filename="package://4C2/meshes/l_2.STL" />
      </geometry>
    </collision>
  </link>
  <joint
    name="l_2_joint"
    type="revolute">
    <origin
      xyz="0 0 0"
      rpy="0 0 0" />
    <parent
      link="l_2_base" />
    <child
      link="l_2" />
    <axis
      xyz="0 0 -1" />
    <limit
      lower="0"
      upper="1"
      effort="1"
      velocity="2" />
    <mimic
        joint="gripper_joint"
        multiplier="1"
        offset="0" />
  </joint>
  <gazebo reference="base_link">
    <material>Gazebo/DarkGrey</material>
  </gazebo>
  
  <gazebo reference="r_1">
    <material>Gazebo/DarkGrey</material>
  </gazebo>
  
  <gazebo reference="r_2_base">
    <material>Gazebo/White</material>
  </gazebo>
  
  <gazebo reference="r_2">
    <material>Gazebo/DarkGrey</material>
  </gazebo>
  
  <gazebo reference="r_3">
    <material>Gazebo/Grey</material>
  </gazebo>
  
  <gazebo reference="l_1">
    <material>Gazebo/DarkGrey</material>
  </gazebo>
  
  <gazebo reference="l_2_base">
    <material>Gazebo/White</material>
  </gazebo>
  
  <gazebo reference="l_2">
    <material>Gazebo/DarkGrey</material>
  </gazebo>
  
  <gazebo reference="l_3">
    <material>Gazebo/Grey</material>
  </gazebo>
</robot>
