<?xml version="1.0" ?>
<!-- =================================================================================== -->
<!-- |    This document was autogenerated by xacro from /usr1/home/semathew/r2d3_isaac/isaac_sim/urdf/r2d3_v1.urdf.xacro | -->
<!-- |    EDITING THIS FILE BY HAND IS NOT RECOMMENDED                                 | -->
<!-- =================================================================================== -->
<!--
  r2d3_v1.urdf.xacro

  V1 composition wrapper for Isaac Sim. Combines:
    - the upstream dual_rm_75b_description URDF (arms + lift + AGV + hands)
    - one head-mounted Intel RealSense D435 (head_link2, +0.05 m forward)
    - two parallel grippers at {l,r}_hand_base_link (custom finger sub-assembly)

  Render via `render.sh` (or directly: `xacro r2d3_v1.urdf.xacro -o r2d3_v1.urdf`)
  from inside a ROS2 environment where dual_rm_75b_description and
  realsense2_description are findable by `$(find ...)`.

  The rendered output is consumed by scripts/urdf_to_usd.py inside the
  Isaac Sim container.
-->
<robot name="r2d3_v1">
  <link name="base_link_underpan">
    <inertial>
      <origin rpy="0 0 0" xyz="-0.012628 -0.016092 -0.060646"/>
      <mass value="2.5521"/>
      <inertia ixx="0.066197" ixy="7.0297E-05" ixz="0.00017628" iyy="0.034903" iyz="-0.00059595" izz="0.097938"/>
    </inertial>
    <visual>
      <origin rpy="0 0 0" xyz="0 0 0"/>
      <geometry>
        <box size="0.001 0.001 0.001"/>
      </geometry>
      <material name="unnamed_001">
        <color rgba="0.79216 0.81961 0.93333 1"/>
      </material>
    </visual>
    <collision>
      <origin rpy="0 0 0" xyz="0 0 0"/>
      <geometry>
        <box size="0.001 0.001 0.001"/>
      </geometry>
    </collision>
  </link>
  <link name="link_right_wheel">
    <inertial>
      <origin rpy="0 0 0" xyz="-0.024898 2.5665E-18 0"/>
      <mass value="1.0523"/>
      <inertia ixx="0.0033125" ixy="1.5953E-19" ixz="1.2287E-20" iyy="0.0018066" iyz="2.5666E-19" izz="0.0018066"/>
    </inertial>
    <visual>
      <origin rpy="0 0 0" xyz="0 0 0"/>
      <geometry>
        <box size="0.001 0.001 0.001"/>
      </geometry>
      <material name="unnamed_002">
        <color rgba="0.79216 0.81961 0.93333 1"/>
      </material>
    </visual>
    <collision>
      <origin rpy="0 0 0" xyz="0 0 0"/>
      <geometry>
        <box size="0.001 0.001 0.001"/>
      </geometry>
    </collision>
  </link>
  <link name="link_left_wheel">
    <inertial>
      <origin rpy="0 0 0" xyz="0.025224 -8.8034E-15 0"/>
      <mass value="1.0734"/>
      <inertia ixx="0.0033996" ixy="-5.0277E-16" ixz="9.2981E-21" iyy="0.0019593" iyz="3.7534E-19" izz="0.0019593"/>
    </inertial>
    <visual>
      <origin rpy="0 0 0" xyz="0 0 0"/>
      <geometry>
        <box size="0.001 0.001 0.001"/>
      </geometry>
      <material name="unnamed_003">
        <color rgba="0.79216 0.81961 0.93333 1"/>
      </material>
    </visual>
    <collision>
      <origin rpy="0 0 0" xyz="0 0 0"/>
      <geometry>
        <box size="0.001 0.001 0.001"/>
      </geometry>
    </collision>
  </link>
  <link name="link_swivel_wheel_1_1">
    <inertial>
      <origin rpy="0 0 0" xyz="0.00067987 -0.0050012 -0.013414"/>
      <mass value="0.088835"/>
      <inertia ixx="3.1679E-05" ixy="2.0129E-08" ixz="2.7021E-08" iyy="3.9438E-05" iyz="-3.2776E-06" izz="4.6143E-05"/>
    </inertial>
    <visual>
      <origin rpy="0 0 0" xyz="0 0 0"/>
      <geometry>
        <box size="0.001 0.001 0.001"/>
      </geometry>
      <material name="unnamed_004">
        <color rgba="0.79216 0.81961 0.93333 1"/>
      </material>
    </visual>
    <collision>
      <origin rpy="0 0 0" xyz="0 0 0"/>
      <geometry>
        <box size="0.001 0.001 0.001"/>
      </geometry>
    </collision>
  </link>
  <link name="link_swivel_wheel_1_2">
    <inertial>
      <origin rpy="0 0 0" xyz="0.0010651 2.2204E-16 9.4369E-16"/>
      <mass value="0.12664"/>
      <inertia ixx="0.00011169" ixy="1.1345E-14" ixz="2.2064E-14" iyy="6.0838E-05" iyz="1.7051E-09" izz="6.084E-05"/>
    </inertial>
    <visual>
      <origin rpy="0 0 0" xyz="0 0 0"/>
      <geometry>
        <box size="0.001 0.001 0.001"/>
      </geometry>
      <material name="unnamed_005">
        <color rgba="0.79216 0.81961 0.93333 1"/>
      </material>
    </visual>
    <collision>
      <origin rpy="0 0 0" xyz="0 0 0"/>
      <geometry>
        <box size="0.001 0.001 0.001"/>
      </geometry>
    </collision>
  </link>
  <link name="link_swivel_wheel_2_1">
    <inertial>
      <origin rpy="0 0 0" xyz="0.00067987 -0.0050012 -0.013414"/>
      <mass value="0.088835"/>
      <inertia ixx="3.1679E-05" ixy="2.0129E-08" ixz="2.7021E-08" iyy="3.9438E-05" iyz="-3.2776E-06" izz="4.6143E-05"/>
    </inertial>
    <visual>
      <origin rpy="0 0 0" xyz="0 0 0"/>
      <geometry>
        <box size="0.001 0.001 0.001"/>
      </geometry>
      <material name="unnamed_006">
        <color rgba="0.79216 0.81961 0.93333 1"/>
      </material>
    </visual>
    <collision>
      <origin rpy="0 0 0" xyz="0 0 0"/>
      <geometry>
        <box size="0.001 0.001 0.001"/>
      </geometry>
    </collision>
  </link>
  <link name="link_swivel_wheel_2_2">
    <inertial>
      <origin rpy="0 0 0" xyz="0.0010651 6.1062E-16 7.7716E-16"/>
      <mass value="0.12664"/>
      <inertia ixx="0.00011169" ixy="1.9869E-14" ixz="1.4856E-14" iyy="6.084E-05" iyz="2.0109E-09" izz="6.0838E-05"/>
    </inertial>
    <visual>
      <origin rpy="0 0 0" xyz="0 0 0"/>
      <geometry>
        <box size="0.001 0.001 0.001"/>
      </geometry>
      <material name="unnamed_007">
        <color rgba="0.79216 0.81961 0.93333 1"/>
      </material>
    </visual>
    <collision>
      <origin rpy="0 0 0" xyz="0 0 0"/>
      <geometry>
        <box size="0.001 0.001 0.001"/>
      </geometry>
    </collision>
  </link>
  <link name="link_swivel_wheel_3_1">
    <inertial>
      <origin rpy="0 0 0" xyz="0.00067987 -0.0050012 -0.013414"/>
      <mass value="0.088835"/>
      <inertia ixx="3.1679E-05" ixy="2.0129E-08" ixz="2.7021E-08" iyy="3.9438E-05" iyz="-3.2776E-06" izz="4.6143E-05"/>
    </inertial>
    <visual>
      <origin rpy="0 0 0" xyz="0 0 0"/>
      <geometry>
        <box size="0.001 0.001 0.001"/>
      </geometry>
      <material name="unnamed_008">
        <color rgba="0.79216 0.81961 0.93333 1"/>
      </material>
    </visual>
    <collision>
      <origin rpy="0 0 0" xyz="0 0 0"/>
      <geometry>
        <box size="0.001 0.001 0.001"/>
      </geometry>
    </collision>
  </link>
  <link name="link_swivel_wheel_3_2">
    <inertial>
      <origin rpy="0 0 0" xyz="0.0010651 -3.3307E-16 8.8818E-16"/>
      <mass value="0.12664"/>
      <inertia ixx="0.00011169" ixy="-1.8513E-15" ixz="2.474E-14" iyy="6.0837E-05" iyz="-3.1204E-10" izz="6.0841E-05"/>
    </inertial>
    <visual>
      <origin rpy="0 0 0" xyz="0 0 0"/>
      <geometry>
        <box size="0.001 0.001 0.001"/>
      </geometry>
      <material name="unnamed_009">
        <color rgba="0.79216 0.81961 0.93333 1"/>
      </material>
    </visual>
    <collision>
      <origin rpy="0 0 0" xyz="0 0 0"/>
      <geometry>
        <box size="0.001 0.001 0.001"/>
      </geometry>
    </collision>
  </link>
  <link name="link_swivel_wheel_4_1">
    <inertial>
      <origin rpy="0 0 0" xyz="0.00067987 -0.0050012 -0.0094542"/>
      <mass value="0.088835"/>
      <inertia ixx="3.1679E-05" ixy="2.0129E-08" ixz="2.7021E-08" iyy="3.9438E-05" iyz="-3.2776E-06" izz="4.6143E-05"/>
    </inertial>
    <visual>
      <origin rpy="0 0 0" xyz="0 0 0"/>
      <geometry>
        <box size="0.001 0.001 0.001"/>
      </geometry>
      <material name="unnamed_010">
        <color rgba="0.79216 0.81961 0.93333 1"/>
      </material>
    </visual>
    <collision>
      <origin rpy="0 0 0" xyz="0 0 0"/>
      <geometry>
        <box size="0.001 0.001 0.001"/>
      </geometry>
    </collision>
  </link>
  <link name="link_swivel_wheel_4_2">
    <inertial>
      <origin rpy="0 0 0" xyz="0.0010651 -4.996E-16 7.494E-16"/>
      <mass value="0.12664"/>
      <inertia ixx="0.00011169" ixy="-7.4776E-15" ixz="2.3656E-14" iyy="6.0837E-05" iyz="-1.205E-09" izz="6.0841E-05"/>
    </inertial>
    <visual>
      <origin rpy="0 0 0" xyz="0 0 0"/>
      <geometry>
        <box size="0.001 0.001 0.001"/>
      </geometry>
      <material name="unnamed_011">
        <color rgba="0.79216 0.81961 0.93333 1"/>
      </material>
    </visual>
    <collision>
      <origin rpy="0 0 0" xyz="0 0 0"/>
      <geometry>
        <box size="0.001 0.001 0.001"/>
      </geometry>
    </collision>
  </link>
  <joint name="joint_right_wheel" type="fixed">
    <origin rpy="0 0 0" xyz="-0.148 0.015574 -0.153"/>
    <parent link="base_link_underpan"/>
    <child link="link_right_wheel"/>
    <axis xyz="1 0 0"/>
    <limit effort="100" velocity="10"/>
  </joint>
  <joint name="joint_left_wheel" type="fixed">
    <origin rpy="0 0 0" xyz="0.148 0.015574 -0.153"/>
    <parent link="base_link_underpan"/>
    <child link="link_left_wheel"/>
    <axis xyz="-1 0 0"/>
    <limit effort="100" velocity="10"/>
  </joint>
  <joint name="joint_swivel_wheel_1_1" type="fixed">
    <origin rpy="0 0 0" xyz="0.124 -0.17843 -0.16254"/>
    <parent link="base_link_underpan"/>
    <child link="link_swivel_wheel_1_1"/>
    <axis xyz="0 0 1"/>
  </joint>
  <joint name="joint_swivel_wheel_1_2" type="fixed">
    <origin rpy="0 0 0" xyz="-0.0035 -0.022 -0.04516"/>
    <parent link="link_swivel_wheel_1_1"/>
    <child link="link_swivel_wheel_1_2"/>
    <axis xyz="1 0 0"/>
  </joint>
  <joint name="joint_swivel_wheel_2_1" type="fixed">
    <origin rpy="0 0 0" xyz="-0.126 0.22157 -0.16254"/>
    <parent link="base_link_underpan"/>
    <child link="link_swivel_wheel_2_1"/>
    <axis xyz="0 0 1"/>
  </joint>
  <joint name="joint_swivel_wheel_2_2" type="fixed">
    <origin rpy="0 0 0" xyz="-0.0035 -0.022 -0.04516"/>
    <parent link="link_swivel_wheel_2_1"/>
    <child link="link_swivel_wheel_2_2"/>
    <axis xyz="1 0 0"/>
  </joint>
  <joint name="joint_swivel_wheel_3_1" type="fixed">
    <origin rpy="0 0 0" xyz="0.124 0.22157 -0.16254"/>
    <parent link="base_link_underpan"/>
    <child link="link_swivel_wheel_3_1"/>
    <axis xyz="0 0 1"/>
  </joint>
  <joint name="joint_swivel_wheel_3_2" type="fixed">
    <origin rpy="0 0 0" xyz="-0.0035 -0.022 -0.04516"/>
    <parent link="link_swivel_wheel_3_1"/>
    <child link="link_swivel_wheel_3_2"/>
    <axis xyz="1 0 0"/>
  </joint>
  <joint name="joint_swivel_wheel_4_1" type="fixed">
    <origin rpy="0 0 0" xyz="-0.126 -0.17843 -0.1665"/>
    <parent link="base_link_underpan"/>
    <child link="link_swivel_wheel_4_1"/>
    <axis xyz="0 0 1"/>
  </joint>
  <joint name="joint_swivel_wheel_4_2" type="fixed">
    <origin rpy="0 0 0" xyz="-0.0035 -0.022 -0.0412"/>
    <parent link="link_swivel_wheel_4_1"/>
    <child link="link_swivel_wheel_4_2"/>
    <axis xyz="1 0 0"/>
  </joint>
  <link name="body_base_link">
    <inertial>
      <origin rpy="0 0 0" xyz="-0.0002128 -0.02749 0.37118"/>
      <mass value="12.159"/>
      <inertia ixx="0.69175" ixy="3.0303E-06" ixz="-1.7947E-05" iyy="0.68839" iyz="0.012363" izz="0.15316"/>
    </inertial>
    <visual>
      <origin rpy="0 0 0" xyz="0 0 0"/>
      <geometry>
        <box size="0.001 0.001 0.001"/>
      </geometry>
      <material name="unnamed_012">
        <color rgba="0.79216 0.81961 0.93333 1"/>
      </material>
    </visual>
    <collision>
      <origin rpy="0 0 0" xyz="0 0 0"/>
      <geometry>
        <box size="0.001 0.001 0.001"/>
      </geometry>
    </collision>
  </link>
  <link name="platform_base_link">
    <inertial>
      <origin rpy="0 0 0" xyz="-4.8033E-05 -0.05292 0.00070789"/>
      <mass value="2.8992"/>
      <inertia ixx="0.013327" ixy="3.14E-06" ixz="3.5257E-06" iyy="0.032331" iyz="6.163E-05" izz="0.021546"/>
    </inertial>
    <visual>
      <origin rpy="0 0 0" xyz="0 0 0"/>
      <geometry>
        <box size="0.001 0.001 0.001"/>
      </geometry>
      <material name="unnamed_013">
        <color rgba="0.79216 0.81961 0.93333 1"/>
      </material>
    </visual>
    <collision>
      <origin rpy="0 0 0" xyz="0 0 0"/>
      <geometry>
        <box size="0.001 0.001 0.001"/>
      </geometry>
    </collision>
  </link>
  <link name="head_link1">
    <inertial>
      <origin rpy="0 0 0" xyz="-0.00017562 -0.015989 0.024926"/>
      <mass value="0.049513"/>
      <inertia ixx="1.6251E-05" ixy="-4.4281E-09" ixz="7.808E-08" iyy="2.2171E-05" iyz="-4.661E-07" izz="1.3605E-05"/>
    </inertial>
    <visual>
      <origin rpy="0 0 0" xyz="0 0 0"/>
      <geometry>
        <box size="0.001 0.001 0.001"/>
      </geometry>
      <material name="unnamed_014">
        <color rgba="0.79216 0.81961 0.93333 1"/>
      </material>
    </visual>
    <collision>
      <origin rpy="0 0 0" xyz="0 0 0"/>
      <geometry>
        <box size="0.001 0.001 0.001"/>
      </geometry>
    </collision>
  </link>
  <link name="head_link2">
    <inertial>
      <origin rpy="0 0 0" xyz="-0.00051349 -0.027144 0.0551"/>
      <mass value="0.23639"/>
      <inertia ixx="0.00025664" ixy="-1.6537E-08" ixz="1.3993E-07" iyy="0.0005615" iyz="1.8036E-05" izz="0.00052625"/>
    </inertial>
    <visual>
      <origin rpy="0 0 0" xyz="0 0 0"/>
      <geometry>
        <box size="0.001 0.001 0.001"/>
      </geometry>
      <material name="unnamed_015">
        <color rgba="0.79216 0.81961 0.93333 1"/>
      </material>
    </visual>
    <collision>
      <origin rpy="0 0 0" xyz="0 0 0"/>
      <geometry>
        <box size="0.001 0.001 0.001"/>
      </geometry>
    </collision>
  </link>
  <link name="camera_link">
    <inertial>
      <origin rpy="0 0 0" xyz="0.0016556 -0.01252 1.2156E-05"/>
      <mass value="0.049778"/>
      <inertia ixx="4.8577E-06" ixy="4.3442E-07" ixz="-6.2436E-10" iyy="3.075E-05" iyz="6.4645E-10" izz="3.0901E-05"/>
    </inertial>
    <visual>
      <origin rpy="0 0 0" xyz="0 0 0"/>
      <geometry>
        <box size="0.001 0.001 0.001"/>
      </geometry>
      <material name="unnamed_016">
        <color rgba="0.79216 0.81961 0.93333 1"/>
      </material>
    </visual>
    <collision>
      <origin rpy="0 0 0" xyz="0 0 0"/>
      <geometry>
        <box size="0.001 0.001 0.001"/>
      </geometry>
    </collision>
  </link>
  <joint name="platform_joint" type="prismatic">
    <origin rpy="0 0 0" xyz="0 -0.11663 0.271"/>
    <parent link="body_base_link"/>
    <child link="platform_base_link"/>
    <axis xyz="0 0 1"/>
    <limit effort="60" lower="0" upper="1" velocity="0.15"/>
  <dynamics damping="1.0" friction="0.1"/></joint>
  <joint name="head_joint1" type="revolute">
    <origin rpy="0 0 0" xyz="0 -0.1018 0.126"/>
    <parent link="platform_base_link"/>
    <child link="head_link1"/>
    <axis xyz="0 0 1"/>
    <limit effort="2" lower="-1.256" upper="1.256" velocity="1.57"/>
  <dynamics damping="1.0" friction="0.1"/></joint>
  <joint name="head_joint2" type="revolute">
    <origin rpy="0 0 0" xyz="0 -0.02 0.044"/>
    <parent link="head_link1"/>
    <child link="head_link2"/>
    <axis xyz="0 -1 0"/>
    <limit effort="2" lower="-0.419" upper="0.419" velocity="1.57"/>
  <dynamics damping="1.0" friction="0.1"/></joint>
  <joint name="camera_joint" type="fixed">
    <origin rpy="0 0 0" xyz="-0.0032391 -0.051866 0.061606"/>
    <parent link="head_link2"/>
    <child link="camera_link"/>
    <axis xyz="0 0 0"/>
  </joint>
  <link name="l_hand_link">
    <inertial>
      <origin rpy="0 0 0" xyz="-0.0032674 -0.0073505 0.084948"/>
      <mass value="0.19134"/>
      <inertia ixx="0.00048203" ixy="-4.1698E-05" ixz="-5.5358E-06" iyy="0.00051126" iyz="-2.6069E-06" izz="0.00019085"/>
    </inertial>
    <visual>
      <origin rpy="0 0 0" xyz="0 0 0"/>
      <geometry>
        <box size="0.001 0.001 0.001"/>
      </geometry>
      <material name="unnamed_017">
        <color rgba="0.75294 0.75294 0.75294 1"/>
      </material>
    </visual>
    <collision>
      <origin rpy="0 0 0" xyz="0 0 0"/>
      <geometry>
        <box size="0.001 0.001 0.001"/>
      </geometry>
    </collision>
  </link>
  <link name="r_hand">
    <inertial>
      <origin rpy="0 0 0" xyz="-0.0077366 0.0020217 0.084945"/>
      <mass value="0.19137"/>
      <inertia ixx="0.00045852" ixy="-2.2207E-05" ixz="-5.5348E-06" iyy="0.00053494" iyz="-2.5678E-06" izz="0.00019084"/>
    </inertial>
    <visual>
      <origin rpy="0 0 0" xyz="0 0 0"/>
      <geometry>
        <box size="0.001 0.001 0.001"/>
      </geometry>
      <material name="unnamed_018">
        <color rgba="0.75294 0.75294 0.75294 1"/>
      </material>
    </visual>
    <collision>
      <origin rpy="0 0 0" xyz="0 0 0"/>
      <geometry>
        <box size="0.001 0.001 0.001"/>
      </geometry>
    </collision>
  </link>
  <link name="l_base_link1">
    <inertial>
      <origin rpy="0 0 0" xyz="-3.58E-05 -0.0056915 0.024464"/>
      <mass value="0.23441"/>
      <inertia ixx="0.00027369" ixy="6.5702E-08" ixz="2.7812E-09" iyy="0.000264" iyz="-1.6355E-06" izz="0.00036679"/>
    </inertial>
    <visual>
      <origin rpy="0 0 0" xyz="0 0 0"/>
      <geometry>
        <box size="0.001 0.001 0.001"/>
      </geometry>
      <material name="unnamed_019">
        <color rgba="0.79216 0.81961 0.93333 1"/>
      </material>
    </visual>
    <collision>
      <origin rpy="0 0 0" xyz="0 0 0"/>
      <geometry>
        <box size="0.001 0.001 0.001"/>
      </geometry>
    </collision>
  </link>
  <link name="l_link1">
    <inertial>
      <origin rpy="0 0 0" xyz="2.9692E-07 0.025188 -0.021107"/>
      <mass value="0.59353"/>
      <inertia ixx="0.0012661" ixy="-2.1134E-09" ixz="-5.3685E-09" iyy="0.00056131" iyz="-0.00021118" izz="0.0011816"/>
    </inertial>
    <visual>
      <origin rpy="0 0 0" xyz="0 0 0"/>
      <geometry>
        <box size="0.001 0.001 0.001"/>
      </geometry>
      <material name="unnamed_020">
        <color rgba="0.79216 0.81961 0.93333 1"/>
      </material>
    </visual>
    <collision>
      <origin rpy="0 0 0" xyz="0 0 0"/>
      <geometry>
        <box size="0.001 0.001 0.001"/>
      </geometry>
    </collision>
  </link>
  <link name="l_link2">
    <inertial>
      <origin rpy="0 0 0" xyz="3.7598E-07 0.011077 0.07613"/>
      <mass value="0.43285"/>
      <inertia ixx="0.0012584" ixy="7.8046E-10" ixz="3.3823E-09" iyy="0.0012224" iyz="0.00027899" izz="0.00031747"/>
    </inertial>
    <visual>
      <origin rpy="0 0 0" xyz="0 0 0"/>
      <geometry>
        <box size="0.001 0.001 0.001"/>
      </geometry>
      <material name="unnamed_021">
        <color rgba="0.79216 0.81961 0.93333 1"/>
      </material>
    </visual>
    <collision>
      <origin rpy="0 0 0" xyz="0 0 0"/>
      <geometry>
        <box size="0.001 0.001 0.001"/>
      </geometry>
    </collision>
  </link>
  <link name="l_link3">
    <inertial>
      <origin rpy="0 0 0" xyz="1.1341E-07 0.027347 -0.023544"/>
      <mass value="0.43132"/>
      <inertia ixx="0.00079434" ixy="1.4278E-09" ixz="2.8253E-09" iyy="0.00031506" iyz="-0.00014262" izz="0.00073038"/>
    </inertial>
    <visual>
      <origin rpy="0 0 0" xyz="0 0 0"/>
      <geometry>
        <box size="0.001 0.001 0.001"/>
      </geometry>
      <material name="unnamed_022">
        <color rgba="0.79216 0.81961 0.93333 1"/>
      </material>
    </visual>
    <collision>
      <origin rpy="0 0 0" xyz="0 0 0"/>
      <geometry>
        <box size="0.001 0.001 0.001"/>
      </geometry>
    </collision>
  </link>
  <link name="l_link4">
    <inertial>
      <origin rpy="0 0 0" xyz="4.7315E-06 0.010268 0.059592"/>
      <mass value="0.28963"/>
      <inertia ixx="0.00063737" ixy="-3.5036E-08" ixz="6.2577E-08" iyy="0.00061418" iyz="0.00014461" izz="0.00015649"/>
    </inertial>
    <visual>
      <origin rpy="0 0 0" xyz="0 0 0"/>
      <geometry>
        <box size="0.001 0.001 0.001"/>
      </geometry>
      <material name="unnamed_023">
        <color rgba="0.79216 0.81961 0.93333 1"/>
      </material>
    </visual>
    <collision>
      <origin rpy="0 0 0" xyz="0 0 0"/>
      <geometry>
        <box size="0.001 0.001 0.001"/>
      </geometry>
    </collision>
  </link>
  <link name="l_link5">
    <inertial>
      <origin rpy="0 0 0" xyz="2.93E-07 0.02154 -0.018042"/>
      <mass value="0.23942"/>
      <inertia ixx="0.00028595" ixy="-1.4023E-09" ixz="-2.3584E-09" iyy="0.0001199" iyz="-4.424E-05" izz="0.00026273"/>
    </inertial>
    <visual>
      <origin rpy="0 0 0" xyz="0 0 0"/>
      <geometry>
        <box size="0.001 0.001 0.001"/>
      </geometry>
      <material name="unnamed_024">
        <color rgba="0.79216 0.81961 0.93333 1"/>
      </material>
    </visual>
    <collision>
      <origin rpy="0 0 0" xyz="0 0 0"/>
      <geometry>
        <box size="0.001 0.001 0.001"/>
      </geometry>
    </collision>
  </link>
  <link name="l_link6">
    <inertial>
      <origin rpy="0 0 0" xyz="4.2445E-06 0.007067 0.059381"/>
      <mass value="0.21879"/>
      <inertia ixx="0.00035053" ixy="-1.6558E-08" ixz="2.8592E-08" iyy="0.00033447" iyz="7.824E-05" izz="0.00010492"/>
    </inertial>
    <visual>
      <origin rpy="0 0 0" xyz="0 0 0"/>
      <geometry>
        <box size="0.001 0.001 0.001"/>
      </geometry>
      <material name="unnamed_025">
        <color rgba="0.79216 0.81961 0.93333 1"/>
      </material>
    </visual>
    <collision>
      <origin rpy="0 0 0" xyz="0 0 0"/>
      <geometry>
        <box size="0.001 0.001 0.001"/>
      </geometry>
    </collision>
  </link>
  <link name="l_link7">
    <inertial>
      <origin rpy="0 0 0" xyz="-0.028763 5.1529E-06 0.025085"/>
      <mass value="0.22147"/>
      <inertia ixx="0.0001376" ixy="-5.7487E-08" ixz="1.6636E-05" iyy="0.00026856" iyz="-1.7799E-08" izz="0.00035278"/>
    </inertial>
    <visual>
      <origin rpy="0 0 0" xyz="0 0 0"/>
      <geometry>
        <box size="0.001 0.001 0.001"/>
      </geometry>
      <material name="unnamed_026">
        <color rgba="0.79216 0.81961 0.93333 1"/>
      </material>
    </visual>
    <collision>
      <origin rpy="0 0 0" xyz="0 0 0"/>
      <geometry>
        <box size="0.001 0.001 0.001"/>
      </geometry>
    </collision>
  </link>
  <joint name="l_joint1" type="revolute">
    <origin rpy="-1.5708 0 0" xyz="0 0 0.187"/>
    <parent link="l_base_link1"/>
    <child link="l_link1"/>
    <axis xyz="0 -1 0"/>
    <limit effort="60" lower="-3.11" upper="3.11" velocity="3.14"/>
  <dynamics damping="1.0" friction="0.1"/></joint>
  <joint name="l_joint2" type="revolute">
    <origin rpy="1.5708 0 0" xyz="0 0 0"/>
    <parent link="l_link1"/>
    <child link="l_link2"/>
    <axis xyz="0 1 0"/>
    <limit effort="60" lower="-2.27" upper="2.27" velocity="3.14"/>
  <dynamics damping="1.0" friction="0.1"/></joint>
  <joint name="l_joint3" type="revolute">
    <origin rpy="-1.5708 0 0" xyz="0 0 0.256"/>
    <parent link="l_link2"/>
    <child link="l_link3"/>
    <axis xyz="0 1 0"/>
    <limit effort="30" lower="-3.11" upper="3.11" velocity="3.925"/>
  <dynamics damping="1.0" friction="0.1"/></joint>
  <joint name="l_joint4" type="revolute">
    <origin rpy="1.5708 0 0" xyz="0 0 0"/>
    <parent link="l_link3"/>
    <child link="l_link4"/>
    <axis xyz="0 1 0"/>
    <limit effort="30" lower="-2.36" upper="2.36" velocity="3.925"/>
  <dynamics damping="1.0" friction="0.1"/></joint>
  <joint name="l_joint5" type="revolute">
    <origin rpy="-1.5708 0 0" xyz="0 -0.00030001 0.21"/>
    <parent link="l_link4"/>
    <child link="l_link5"/>
    <axis xyz="0 1 0"/>
    <limit effort="10" lower="-3.11" upper="3.11" velocity="3.925"/>
  <dynamics damping="1.0" friction="0.1"/></joint>
  <joint name="l_joint6" type="revolute">
    <origin rpy="1.5708 0 0" xyz="0 0 0"/>
    <parent link="l_link5"/>
    <child link="l_link6"/>
    <axis xyz="0 -1 0"/>
    <limit effort="10" lower="-2.23" upper="2.23" velocity="3.925"/>
  <dynamics damping="1.0" friction="0.1"/></joint>
  <joint name="l_joint7" type="revolute">
    <origin rpy="0 0 3.14" xyz="0 -0.00029971 0.115"/>
    <parent link="l_link6"/>
    <child link="l_link7"/>
    <axis xyz="0 0 -1"/>
    <limit effort="10" lower="-6.28" upper="6.28" velocity="3.925"/>
  <dynamics damping="1.0" friction="0.1"/></joint>
  <link name="r_base_link1">
    <inertial>
      <origin rpy="0 0 0" xyz="-4.8022E-05 0.0056915 0.024715"/>
      <mass value="0.23441"/>
      <inertia ixx="0.00027369" ixy="6.5702E-08" ixz="-3.2599E-09" iyy="0.000264" iyz="1.6355E-06" izz="0.00036679"/>
    </inertial>
    <visual>
      <origin rpy="0 0 0" xyz="0 0 0"/>
      <geometry>
        <box size="0.001 0.001 0.001"/>
      </geometry>
      <material name="unnamed_027">
        <color rgba="0.79216 0.81961 0.93333 1"/>
      </material>
    </visual>
    <collision>
      <origin rpy="0 0 0" xyz="0 0 0"/>
      <geometry>
        <box size="0.001 0.001 0.001"/>
      </geometry>
    </collision>
  </link>
  <link name="r_link1">
    <inertial>
      <origin rpy="0 0 0" xyz="2.8966E-07 0.025188 -0.021107"/>
      <mass value="0.59353"/>
      <inertia ixx="0.0012661" ixy="-2.0397E-09" ixz="-5.3423E-09" iyy="0.00056131" iyz="-0.00021118" izz="0.0011816"/>
    </inertial>
    <visual>
      <origin rpy="0 0 0" xyz="0 0 0"/>
      <geometry>
        <box size="0.001 0.001 0.001"/>
      </geometry>
      <material name="unnamed_028">
        <color rgba="0.79216 0.81961 0.93333 1"/>
      </material>
    </visual>
    <collision>
      <origin rpy="0 0 0" xyz="0 0 0"/>
      <geometry>
        <box size="0.001 0.001 0.001"/>
      </geometry>
    </collision>
  </link>
  <link name="r_link2">
    <inertial>
      <origin rpy="0 0 0" xyz="3.7069E-07 0.011077 0.07613"/>
      <mass value="0.43285"/>
      <inertia ixx="0.0012584" ixy="7.782E-10" ixz="3.39E-09" iyy="0.0012224" iyz="0.00027899" izz="0.00031747"/>
    </inertial>
    <visual>
      <origin rpy="0 0 0" xyz="0 0 0"/>
      <geometry>
        <box size="0.001 0.001 0.001"/>
      </geometry>
      <material name="unnamed_029">
        <color rgba="0.79216 0.81961 0.93333 1"/>
      </material>
    </visual>
    <collision>
      <origin rpy="0 0 0" xyz="0 0 0"/>
      <geometry>
        <box size="0.001 0.001 0.001"/>
      </geometry>
    </collision>
  </link>
  <link name="r_link3">
    <inertial>
      <origin rpy="0 0 0" xyz="1.192E-07 0.027347 -0.023544"/>
      <mass value="0.43132"/>
      <inertia ixx="0.00079434" ixy="1.4708E-09" ixz="2.8344E-09" iyy="0.00031506" iyz="-0.00014262" izz="0.00073038"/>
    </inertial>
    <visual>
      <origin rpy="0 0 0" xyz="0 0 0"/>
      <geometry>
        <box size="0.001 0.001 0.001"/>
      </geometry>
      <material name="unnamed_030">
        <color rgba="0.79216 0.81961 0.93333 1"/>
      </material>
    </visual>
    <collision>
      <origin rpy="0 0 0" xyz="0 0 0"/>
      <geometry>
        <box size="0.001 0.001 0.001"/>
      </geometry>
    </collision>
  </link>
  <link name="r_link4">
    <inertial>
      <origin rpy="0 0 0" xyz="4.7388E-06 0.010268 0.059592"/>
      <mass value="0.28963"/>
      <inertia ixx="0.00063737" ixy="-3.5039E-08" ixz="6.2578E-08" iyy="0.00061418" iyz="0.00014461" izz="0.00015649"/>
    </inertial>
    <visual>
      <origin rpy="0 0 0" xyz="0 0 0"/>
      <geometry>
        <box size="0.001 0.001 0.001"/>
      </geometry>
      <material name="unnamed_031">
        <color rgba="0.79216 0.81961 0.93333 1"/>
      </material>
    </visual>
    <collision>
      <origin rpy="0 0 0" xyz="0 0 0"/>
      <geometry>
        <box size="0.001 0.001 0.001"/>
      </geometry>
    </collision>
  </link>
  <link name="r_link5">
    <inertial>
      <origin rpy="0 0 0" xyz="2.9088E-07 0.02154 -0.018042"/>
      <mass value="0.23942"/>
      <inertia ixx="0.00028595" ixy="-1.386E-09" ixz="-2.3541E-09" iyy="0.0001199" iyz="-4.424E-05" izz="0.00026273"/>
    </inertial>
    <visual>
      <origin rpy="0 0 0" xyz="0 0 0"/>
      <geometry>
        <box size="0.001 0.001 0.001"/>
      </geometry>
      <material name="unnamed_032">
        <color rgba="0.79216 0.81961 0.93333 1"/>
      </material>
    </visual>
    <collision>
      <origin rpy="0 0 0" xyz="0 0 0"/>
      <geometry>
        <box size="0.001 0.001 0.001"/>
      </geometry>
    </collision>
  </link>
  <link name="r_link6">
    <inertial>
      <origin rpy="0 0 0" xyz="4.247E-06 0.0070761 0.05938"/>
      <mass value="0.21879"/>
      <inertia ixx="0.00035053" ixy="-1.6543E-08" ixz="2.8572E-08" iyy="0.0003345" iyz="7.8205E-05" izz="0.0001049"/>
    </inertial>
    <visual>
      <origin rpy="0 0 0" xyz="0 0 0"/>
      <geometry>
        <box size="0.001 0.001 0.001"/>
      </geometry>
      <material name="unnamed_033">
        <color rgba="0.79216 0.81961 0.93333 1"/>
      </material>
    </visual>
    <collision>
      <origin rpy="0 0 0" xyz="0 0 0"/>
      <geometry>
        <box size="0.001 0.001 0.001"/>
      </geometry>
    </collision>
  </link>
  <link name="r_link7">
    <inertial>
      <origin rpy="0 0 0" xyz="-0.028764 5.1464E-06 0.023085"/>
      <mass value="0.22147"/>
      <inertia ixx="0.0001376" ixy="-5.7488E-08" ixz="1.6634E-05" iyy="0.00026855" iyz="-1.7799E-08" izz="0.00035277"/>
    </inertial>
    <visual>
      <origin rpy="0 0 0" xyz="0 0 0"/>
      <geometry>
        <box size="0.001 0.001 0.001"/>
      </geometry>
      <material name="unnamed_034">
        <color rgba="0.79216 0.81961 0.93333 1"/>
      </material>
    </visual>
    <collision>
      <origin rpy="0 0 0" xyz="0 0 0"/>
      <geometry>
        <box size="0.001 0.001 0.001"/>
      </geometry>
    </collision>
  </link>
  <joint name="r_joint1" type="revolute">
    <origin rpy="-1.5708 0 3.1415" xyz="0 0 0.187"/>
    <parent link="r_base_link1"/>
    <child link="r_link1"/>
    <axis xyz="0 -1 0"/>
    <limit effort="60" lower="-3.11" upper="3.11" velocity="3.14"/>
  <dynamics damping="1.0" friction="0.1"/></joint>
  <joint name="r_joint2" type="revolute">
    <origin rpy="1.5708 0 0" xyz="0 0 0"/>
    <parent link="r_link1"/>
    <child link="r_link2"/>
    <axis xyz="0 1 0"/>
    <limit effort="60" lower="-2.27" upper="2.27" velocity="3.14"/>
  <dynamics damping="1.0" friction="0.1"/></joint>
  <joint name="r_joint3" type="revolute">
    <origin rpy="-1.5708 0 0" xyz="0 0 0.256"/>
    <parent link="r_link2"/>
    <child link="r_link3"/>
    <axis xyz="0 1 0"/>
    <limit effort="30" lower="-3.11" upper="3.11" velocity="3.925"/>
  <dynamics damping="1.0" friction="0.1"/></joint>
  <joint name="r_joint4" type="revolute">
    <origin rpy="1.5708 0 0" xyz="0 0 0"/>
    <parent link="r_link3"/>
    <child link="r_link4"/>
    <axis xyz="0 -1 0"/>
    <limit effort="30" lower="-2.36" upper="2.36" velocity="3.925"/>
  <dynamics damping="1.0" friction="0.1"/></joint>
  <joint name="r_joint5" type="revolute">
    <origin rpy="-1.5708 0 0" xyz="0 -0.00030007 0.21"/>
    <parent link="r_link4"/>
    <child link="r_link5"/>
    <axis xyz="0 1 0"/>
    <limit effort="10" lower="-3.11" upper="3.11" velocity="3.925"/>
  <dynamics damping="1.0" friction="0.1"/></joint>
  <joint name="r_joint6" type="revolute">
    <origin rpy="1.5709 0 0" xyz="0 0 0"/>
    <parent link="r_link5"/>
    <child link="r_link6"/>
    <axis xyz="0 -1 0.00015298"/>
    <limit effort="10" lower="-2.23" upper="2.23" velocity="3.925"/>
  <dynamics damping="1.0" friction="0.1"/></joint>
  <joint name="r_joint7" type="revolute">
    <origin rpy="-0.00015298 0 0" xyz="0 -0.00028182 0.117"/>
    <parent link="r_link6"/>
    <child link="r_link7"/>
    <axis xyz="0 0 -1"/>
    <limit effort="10" lower="-6.28" upper="6.28" velocity="3.925"/>
  <dynamics damping="1.0" friction="0.1"/></joint>
  <joint name="body_base_joint" type="fixed">
    <origin rpy="0 0 0" xyz="0 0 0"/>
    <parent link="base_link_underpan"/>
    <child link="body_base_link"/>
    <axis xyz="1 0 0"/>
    <limit effort="0" velocity="0"/>
  </joint>
  <joint name="r_base_joint1" type="fixed">
    <origin rpy="0 -0.7854 0" xyz="-0.1 -0.1103 0.031645"/>
    <parent link="platform_base_link"/>
    <child link="r_base_link1"/>
    <axis xyz="0 0 0"/>
  </joint>
  <joint name="l_base_joint1" type="fixed">
    <origin rpy="0 -0.7854 3.1416" xyz="0.1 -0.1103 0.031645"/>
    <parent link="platform_base_link"/>
    <child link="l_base_link1"/>
    <axis xyz="0 0 0"/>
  </joint>
  <joint name="r_hand_joint" type="fixed">
    <origin rpy="0 0 0" xyz="0 0 0.0445"/>
    <parent link="r_link7"/>
    <child link="r_hand"/>
    <axis xyz="0 0 -1"/>
    <limit effort="0" lower="0" upper="0" velocity="0"/>
  </joint>
  <joint name="l_hand_joint" type="fixed">
    <origin rpy="0 0 3.1415" xyz="0 0 0.0445"/>
    <parent link="l_link7"/>
    <child link="l_hand_link"/>
    <axis xyz="0 0 0"/>
    <limit effort="0" lower="0" upper="0" velocity="0"/>
  </joint>
  <transmission name="l_joint1_trans">
    <type>transmission_interface/SimpleTransmission</type>
    <joint name="l_joint1">
      <hardwareInterface>PositionJointInterface</hardwareInterface>
    </joint>
    <actuator name="l_joint1_motor">
      <mechanicalReduction>1</mechanicalReduction>
    </actuator>
  </transmission>
  <transmission name="l_joint2_trans">
    <type>transmission_interface/SimpleTransmission</type>
    <joint name="l_joint2">
      <hardwareInterface>PositionJointInterface</hardwareInterface>
    </joint>
    <actuator name="l_joint2_motor">
      <mechanicalReduction>1</mechanicalReduction>
    </actuator>
  </transmission>
  <transmission name="l_joint3_trans">
    <type>transmission_interface/SimpleTransmission</type>
    <joint name="l_joint3">
      <hardwareInterface>PositionJointInterface</hardwareInterface>
    </joint>
    <actuator name="l_joint3_motor">
      <mechanicalReduction>1</mechanicalReduction>
    </actuator>
  </transmission>
  <transmission name="l_joint4_trans">
    <type>transmission_interface/SimpleTransmission</type>
    <joint name="l_joint4">
      <hardwareInterface>PositionJointInterface</hardwareInterface>
    </joint>
    <actuator name="l_joint4_motor">
      <mechanicalReduction>1</mechanicalReduction>
    </actuator>
  </transmission>
  <transmission name="l_joint5_trans">
    <type>transmission_interface/SimpleTransmission</type>
    <joint name="l_joint5">
      <hardwareInterface>PositionJointInterface</hardwareInterface>
    </joint>
    <actuator name="l_joint5_motor">
      <mechanicalReduction>1</mechanicalReduction>
    </actuator>
  </transmission>
  <transmission name="l_joint6_trans">
    <type>transmission_interface/SimpleTransmission</type>
    <joint name="l_joint6">
      <hardwareInterface>PositionJointInterface</hardwareInterface>
    </joint>
    <actuator name="l_joint6_motor">
      <mechanicalReduction>1</mechanicalReduction>
    </actuator>
  </transmission>
  <transmission name="l_joint7_trans">
    <type>transmission_interface/SimpleTransmission</type>
    <joint name="l_joint7">
      <hardwareInterface>PositionJointInterface</hardwareInterface>
    </joint>
    <actuator name="l_joint7_motor">
      <mechanicalReduction>1</mechanicalReduction>
    </actuator>
  </transmission>
  <transmission name="r_joint1_trans">
    <type>transmission_interface/SimpleTransmission</type>
    <joint name="r_joint1">
      <hardwareInterface>PositionJointInterface</hardwareInterface>
    </joint>
    <actuator name="r_joint1_motor">
      <mechanicalReduction>1</mechanicalReduction>
    </actuator>
  </transmission>
  <transmission name="r_joint2_trans">
    <type>transmission_interface/SimpleTransmission</type>
    <joint name="r_joint2">
      <hardwareInterface>PositionJointInterface</hardwareInterface>
    </joint>
    <actuator name="r_joint2_motor">
      <mechanicalReduction>1</mechanicalReduction>
    </actuator>
  </transmission>
  <transmission name="r_joint3_trans">
    <type>transmission_interface/SimpleTransmission</type>
    <joint name="r_joint3">
      <hardwareInterface>PositionJointInterface</hardwareInterface>
    </joint>
    <actuator name="r_joint3_motor">
      <mechanicalReduction>1</mechanicalReduction>
    </actuator>
  </transmission>
  <transmission name="r_joint4_trans">
    <type>transmission_interface/SimpleTransmission</type>
    <joint name="r_joint4">
      <hardwareInterface>PositionJointInterface</hardwareInterface>
    </joint>
    <actuator name="r_joint4_motor">
      <mechanicalReduction>1</mechanicalReduction>
    </actuator>
  </transmission>
  <transmission name="r_joint5_trans">
    <type>transmission_interface/SimpleTransmission</type>
    <joint name="r_joint5">
      <hardwareInterface>PositionJointInterface</hardwareInterface>
    </joint>
    <actuator name="r_joint5_motor">
      <mechanicalReduction>1</mechanicalReduction>
    </actuator>
  </transmission>
  <transmission name="r_joint6_trans">
    <type>transmission_interface/SimpleTransmission</type>
    <joint name="r_joint6">
      <hardwareInterface>PositionJointInterface</hardwareInterface>
    </joint>
    <actuator name="r_joint6_motor">
      <mechanicalReduction>1</mechanicalReduction>
    </actuator>
  </transmission>
  <transmission name="r_joint7_trans">
    <type>transmission_interface/SimpleTransmission</type>
    <joint name="r_joint7">
      <hardwareInterface>PositionJointInterface</hardwareInterface>
    </joint>
    <actuator name="r_joint7_motor">
      <mechanicalReduction>1</mechanicalReduction>
    </actuator>
  </transmission>
  <transmission name="platform_joint_trans">
    <type>transmission_interface/SimpleTransmission</type>
    <joint name="platform_joint">
      <hardwareInterface>PositionJointInterface</hardwareInterface>
    </joint>
    <actuator name="platform_joint_motor">
      <mechanicalReduction>1</mechanicalReduction>
    </actuator>
  </transmission>
  <transmission name="head_joint1_trans">
    <type>transmission_interface/SimpleTransmission</type>
    <joint name="head_joint1">
      <hardwareInterface>PositionJointInterface</hardwareInterface>
    </joint>
    <actuator name="head_joint1_motor">
      <mechanicalReduction>1</mechanicalReduction>
    </actuator>
  </transmission>
  <transmission name="head_joint2_trans">
    <type>transmission_interface/SimpleTransmission</type>
    <joint name="head_joint2">
      <hardwareInterface>PositionJointInterface</hardwareInterface>
    </joint>
    <actuator name="head_joint2_motor">
      <mechanicalReduction>1</mechanicalReduction>
    </actuator>
  </transmission>
  <!-- <xacro:include filename="$(find dual_rm_75b_description)/urdf/common_gazebo.xacro"/> -->
  <material name="aluminum">
    <color rgba="0.5 0.5 0.5 1"/>
  </material>
  <material name="plastic">
    <color rgba="0.1 0.1 0.1 1"/>
  </material>
  <!-- camera body, with origin at bottom screw mount -->
  <joint name="head_camera_joint" type="fixed">
    <origin rpy="0 0 0" xyz="-0.0138391 -0.069366 0.049106"/>
    <parent link="head_link2"/>
    <child link="head_camera_bottom_screw_frame"/>
  </joint>
  <link name="head_camera_bottom_screw_frame"><inertial><origin xyz="0 0 0" rpy="0 0 0"/><mass value="0.001"/><inertia ixx="1e-6" ixy="0" ixz="0" iyy="1e-6" iyz="0" izz="1e-6"/></inertial></link>
  <joint name="head_camera_link_joint" type="fixed">
    <origin rpy="0 0 0" xyz="0.010600000000000002 0.0175 0.0125"/>
    <parent link="head_camera_bottom_screw_frame"/>
    <child link="head_camera_link"/>
  </joint>
  <link name="head_camera_link">
    <visual>
      <origin rpy="0 0 0" xyz="0 -0.0175 0"/>
      <geometry>
        <box size="0.02505 0.09 0.025"/>
      </geometry>
      <material name="aluminum"/>
    </visual>
    <collision>
      <origin rpy="0 0 0" xyz="0 -0.0175 0"/>
      <geometry>
        <box size="0.02505 0.09 0.025"/>
      </geometry>
    </collision>
    <inertial>
      <!-- The following are not reliable values, and should not be used for modeling -->
      <mass value="0.072"/>
      <origin xyz="0 0 0"/>
      <inertia ixx="0.003881243" ixy="0.0" ixz="0.0" iyy="0.000498940" iyz="0.0" izz="0.003879257"/>
    </inertial>
  </link>
  <!-- camera depth joints and links -->
  <joint name="head_camera_depth_joint" type="fixed">
    <origin rpy="0 0 0" xyz="0 0 0"/>
    <parent link="head_camera_link"/>
    <child link="head_camera_depth_frame"/>
  </joint>
  <link name="head_camera_depth_frame"><inertial><origin xyz="0 0 0" rpy="0 0 0"/><mass value="0.001"/><inertia ixx="1e-6" ixy="0" ixz="0" iyy="1e-6" iyz="0" izz="1e-6"/></inertial></link>
  <joint name="head_camera_depth_optical_joint" type="fixed">
    <origin rpy="-1.5707963267948966 0 -1.5707963267948966" xyz="0 0 0"/>
    <parent link="head_camera_depth_frame"/>
    <child link="head_camera_depth_optical_frame"/>
  </joint>
  <link name="head_camera_depth_optical_frame"><inertial><origin xyz="0 0 0" rpy="0 0 0"/><mass value="0.001"/><inertia ixx="1e-6" ixy="0" ixz="0" iyy="1e-6" iyz="0" izz="1e-6"/></inertial></link>
  <!-- camera left IR joints and links -->
  <joint name="head_camera_infra1_joint" type="fixed">
    <origin rpy="0 0 0" xyz="0 0.0 0"/>
    <parent link="head_camera_link"/>
    <child link="head_camera_infra1_frame"/>
  </joint>
  <link name="head_camera_infra1_frame"><inertial><origin xyz="0 0 0" rpy="0 0 0"/><mass value="0.001"/><inertia ixx="1e-6" ixy="0" ixz="0" iyy="1e-6" iyz="0" izz="1e-6"/></inertial></link>
  <joint name="head_camera_infra1_optical_joint" type="fixed">
    <origin rpy="-1.5707963267948966 0 -1.5707963267948966" xyz="0 0 0"/>
    <parent link="head_camera_infra1_frame"/>
    <child link="head_camera_infra1_optical_frame"/>
  </joint>
  <link name="head_camera_infra1_optical_frame"><inertial><origin xyz="0 0 0" rpy="0 0 0"/><mass value="0.001"/><inertia ixx="1e-6" ixy="0" ixz="0" iyy="1e-6" iyz="0" izz="1e-6"/></inertial></link>
  <!-- camera right IR joints and links -->
  <joint name="head_camera_infra2_joint" type="fixed">
    <origin rpy="0 0 0" xyz="0 -0.05 0"/>
    <parent link="head_camera_link"/>
    <child link="head_camera_infra2_frame"/>
  </joint>
  <link name="head_camera_infra2_frame"><inertial><origin xyz="0 0 0" rpy="0 0 0"/><mass value="0.001"/><inertia ixx="1e-6" ixy="0" ixz="0" iyy="1e-6" iyz="0" izz="1e-6"/></inertial></link>
  <joint name="head_camera_infra2_optical_joint" type="fixed">
    <origin rpy="-1.5707963267948966 0 -1.5707963267948966" xyz="0 0 0"/>
    <parent link="head_camera_infra2_frame"/>
    <child link="head_camera_infra2_optical_frame"/>
  </joint>
  <link name="head_camera_infra2_optical_frame"><inertial><origin xyz="0 0 0" rpy="0 0 0"/><mass value="0.001"/><inertia ixx="1e-6" ixy="0" ixz="0" iyy="1e-6" iyz="0" izz="1e-6"/></inertial></link>
  <!-- camera color joints and links -->
  <joint name="head_camera_color_joint" type="fixed">
    <origin rpy="0 0 0" xyz="0 0.015 0"/>
    <parent link="head_camera_link"/>
    <child link="head_camera_color_frame"/>
  </joint>
  <link name="head_camera_color_frame"><inertial><origin xyz="0 0 0" rpy="0 0 0"/><mass value="0.001"/><inertia ixx="1e-6" ixy="0" ixz="0" iyy="1e-6" iyz="0" izz="1e-6"/></inertial></link>
  <joint name="head_camera_color_optical_joint" type="fixed">
    <origin rpy="-1.5707963267948966 0 -1.5707963267948966" xyz="0 0 0"/>
    <parent link="head_camera_color_frame"/>
    <child link="head_camera_color_optical_frame"/>
  </joint>
  <link name="head_camera_color_optical_frame"><inertial><origin xyz="0 0 0" rpy="0 0 0"/><mass value="0.001"/><inertia ixx="1e-6" ixy="0" ixz="0" iyy="1e-6" iyz="0" izz="1e-6"/></inertial></link>
  <!-- camera body, with origin at bottom screw mount -->
  <joint name="l_wrist_camera_joint" type="fixed">
    <origin rpy="0 -1.5707963 0" xyz="0.05 0.0 0.0"/>
    <parent link="l_link7"/>
    <child link="l_wrist_camera_bottom_screw_frame"/>
  </joint>
  <link name="l_wrist_camera_bottom_screw_frame"><inertial><origin xyz="0 0 0" rpy="0 0 0"/><mass value="0.001"/><inertia ixx="1e-6" ixy="0" ixz="0" iyy="1e-6" iyz="0" izz="1e-6"/></inertial></link>
  <joint name="l_wrist_camera_link_joint" type="fixed">
    <origin rpy="0 0 0" xyz="0.010600000000000002 0.0175 0.0125"/>
    <parent link="l_wrist_camera_bottom_screw_frame"/>
    <child link="l_wrist_camera_link"/>
  </joint>
  <link name="l_wrist_camera_link">
    <visual>
      <origin rpy="0 0 0" xyz="0 -0.0175 0"/>
      <geometry>
        <box size="0.02505 0.09 0.025"/>
      </geometry>
      <material name="aluminum"/>
    </visual>
    <collision>
      <origin rpy="0 0 0" xyz="0 -0.0175 0"/>
      <geometry>
        <box size="0.02505 0.09 0.025"/>
      </geometry>
    </collision>
    <inertial>
      <!-- The following are not reliable values, and should not be used for modeling -->
      <mass value="0.072"/>
      <origin xyz="0 0 0"/>
      <inertia ixx="0.003881243" ixy="0.0" ixz="0.0" iyy="0.000498940" iyz="0.0" izz="0.003879257"/>
    </inertial>
  </link>
  <!-- camera depth joints and links -->
  <joint name="l_wrist_camera_depth_joint" type="fixed">
    <origin rpy="0 0 0" xyz="0 0 0"/>
    <parent link="l_wrist_camera_link"/>
    <child link="l_wrist_camera_depth_frame"/>
  </joint>
  <link name="l_wrist_camera_depth_frame"><inertial><origin xyz="0 0 0" rpy="0 0 0"/><mass value="0.001"/><inertia ixx="1e-6" ixy="0" ixz="0" iyy="1e-6" iyz="0" izz="1e-6"/></inertial></link>
  <joint name="l_wrist_camera_depth_optical_joint" type="fixed">
    <origin rpy="-1.5707963267948966 0 -1.5707963267948966" xyz="0 0 0"/>
    <parent link="l_wrist_camera_depth_frame"/>
    <child link="l_wrist_camera_depth_optical_frame"/>
  </joint>
  <link name="l_wrist_camera_depth_optical_frame"><inertial><origin xyz="0 0 0" rpy="0 0 0"/><mass value="0.001"/><inertia ixx="1e-6" ixy="0" ixz="0" iyy="1e-6" iyz="0" izz="1e-6"/></inertial></link>
  <!-- camera left IR joints and links -->
  <joint name="l_wrist_camera_infra1_joint" type="fixed">
    <origin rpy="0 0 0" xyz="0 0.0 0"/>
    <parent link="l_wrist_camera_link"/>
    <child link="l_wrist_camera_infra1_frame"/>
  </joint>
  <link name="l_wrist_camera_infra1_frame"><inertial><origin xyz="0 0 0" rpy="0 0 0"/><mass value="0.001"/><inertia ixx="1e-6" ixy="0" ixz="0" iyy="1e-6" iyz="0" izz="1e-6"/></inertial></link>
  <joint name="l_wrist_camera_infra1_optical_joint" type="fixed">
    <origin rpy="-1.5707963267948966 0 -1.5707963267948966" xyz="0 0 0"/>
    <parent link="l_wrist_camera_infra1_frame"/>
    <child link="l_wrist_camera_infra1_optical_frame"/>
  </joint>
  <link name="l_wrist_camera_infra1_optical_frame"><inertial><origin xyz="0 0 0" rpy="0 0 0"/><mass value="0.001"/><inertia ixx="1e-6" ixy="0" ixz="0" iyy="1e-6" iyz="0" izz="1e-6"/></inertial></link>
  <!-- camera right IR joints and links -->
  <joint name="l_wrist_camera_infra2_joint" type="fixed">
    <origin rpy="0 0 0" xyz="0 -0.05 0"/>
    <parent link="l_wrist_camera_link"/>
    <child link="l_wrist_camera_infra2_frame"/>
  </joint>
  <link name="l_wrist_camera_infra2_frame"><inertial><origin xyz="0 0 0" rpy="0 0 0"/><mass value="0.001"/><inertia ixx="1e-6" ixy="0" ixz="0" iyy="1e-6" iyz="0" izz="1e-6"/></inertial></link>
  <joint name="l_wrist_camera_infra2_optical_joint" type="fixed">
    <origin rpy="-1.5707963267948966 0 -1.5707963267948966" xyz="0 0 0"/>
    <parent link="l_wrist_camera_infra2_frame"/>
    <child link="l_wrist_camera_infra2_optical_frame"/>
  </joint>
  <link name="l_wrist_camera_infra2_optical_frame"><inertial><origin xyz="0 0 0" rpy="0 0 0"/><mass value="0.001"/><inertia ixx="1e-6" ixy="0" ixz="0" iyy="1e-6" iyz="0" izz="1e-6"/></inertial></link>
  <!-- camera color joints and links -->
  <joint name="l_wrist_camera_color_joint" type="fixed">
    <origin rpy="0 0 0" xyz="0 0.015 0"/>
    <parent link="l_wrist_camera_link"/>
    <child link="l_wrist_camera_color_frame"/>
  </joint>
  <link name="l_wrist_camera_color_frame"><inertial><origin xyz="0 0 0" rpy="0 0 0"/><mass value="0.001"/><inertia ixx="1e-6" ixy="0" ixz="0" iyy="1e-6" iyz="0" izz="1e-6"/></inertial></link>
  <joint name="l_wrist_camera_color_optical_joint" type="fixed">
    <origin rpy="-1.5707963267948966 0 -1.5707963267948966" xyz="0 0 0"/>
    <parent link="l_wrist_camera_color_frame"/>
    <child link="l_wrist_camera_color_optical_frame"/>
  </joint>
  <link name="l_wrist_camera_color_optical_frame"><inertial><origin xyz="0 0 0" rpy="0 0 0"/><mass value="0.001"/><inertia ixx="1e-6" ixy="0" ixz="0" iyy="1e-6" iyz="0" izz="1e-6"/></inertial></link>
  <!-- camera body, with origin at bottom screw mount -->
  <joint name="r_wrist_camera_joint" type="fixed">
    <origin rpy="0 -1.5707963 0" xyz="0.05 0.0 0.0"/>
    <parent link="r_link7"/>
    <child link="r_wrist_camera_bottom_screw_frame"/>
  </joint>
  <link name="r_wrist_camera_bottom_screw_frame"><inertial><origin xyz="0 0 0" rpy="0 0 0"/><mass value="0.001"/><inertia ixx="1e-6" ixy="0" ixz="0" iyy="1e-6" iyz="0" izz="1e-6"/></inertial></link>
  <joint name="r_wrist_camera_link_joint" type="fixed">
    <origin rpy="0 0 0" xyz="0.010600000000000002 0.0175 0.0125"/>
    <parent link="r_wrist_camera_bottom_screw_frame"/>
    <child link="r_wrist_camera_link"/>
  </joint>
  <link name="r_wrist_camera_link">
    <visual>
      <origin rpy="0 0 0" xyz="0 -0.0175 0"/>
      <geometry>
        <box size="0.02505 0.09 0.025"/>
      </geometry>
      <material name="aluminum"/>
    </visual>
    <collision>
      <origin rpy="0 0 0" xyz="0 -0.0175 0"/>
      <geometry>
        <box size="0.02505 0.09 0.025"/>
      </geometry>
    </collision>
    <inertial>
      <!-- The following are not reliable values, and should not be used for modeling -->
      <mass value="0.072"/>
      <origin xyz="0 0 0"/>
      <inertia ixx="0.003881243" ixy="0.0" ixz="0.0" iyy="0.000498940" iyz="0.0" izz="0.003879257"/>
    </inertial>
  </link>
  <!-- camera depth joints and links -->
  <joint name="r_wrist_camera_depth_joint" type="fixed">
    <origin rpy="0 0 0" xyz="0 0 0"/>
    <parent link="r_wrist_camera_link"/>
    <child link="r_wrist_camera_depth_frame"/>
  </joint>
  <link name="r_wrist_camera_depth_frame"><inertial><origin xyz="0 0 0" rpy="0 0 0"/><mass value="0.001"/><inertia ixx="1e-6" ixy="0" ixz="0" iyy="1e-6" iyz="0" izz="1e-6"/></inertial></link>
  <joint name="r_wrist_camera_depth_optical_joint" type="fixed">
    <origin rpy="-1.5707963267948966 0 -1.5707963267948966" xyz="0 0 0"/>
    <parent link="r_wrist_camera_depth_frame"/>
    <child link="r_wrist_camera_depth_optical_frame"/>
  </joint>
  <link name="r_wrist_camera_depth_optical_frame"><inertial><origin xyz="0 0 0" rpy="0 0 0"/><mass value="0.001"/><inertia ixx="1e-6" ixy="0" ixz="0" iyy="1e-6" iyz="0" izz="1e-6"/></inertial></link>
  <!-- camera left IR joints and links -->
  <joint name="r_wrist_camera_infra1_joint" type="fixed">
    <origin rpy="0 0 0" xyz="0 0.0 0"/>
    <parent link="r_wrist_camera_link"/>
    <child link="r_wrist_camera_infra1_frame"/>
  </joint>
  <link name="r_wrist_camera_infra1_frame"><inertial><origin xyz="0 0 0" rpy="0 0 0"/><mass value="0.001"/><inertia ixx="1e-6" ixy="0" ixz="0" iyy="1e-6" iyz="0" izz="1e-6"/></inertial></link>
  <joint name="r_wrist_camera_infra1_optical_joint" type="fixed">
    <origin rpy="-1.5707963267948966 0 -1.5707963267948966" xyz="0 0 0"/>
    <parent link="r_wrist_camera_infra1_frame"/>
    <child link="r_wrist_camera_infra1_optical_frame"/>
  </joint>
  <link name="r_wrist_camera_infra1_optical_frame"><inertial><origin xyz="0 0 0" rpy="0 0 0"/><mass value="0.001"/><inertia ixx="1e-6" ixy="0" ixz="0" iyy="1e-6" iyz="0" izz="1e-6"/></inertial></link>
  <!-- camera right IR joints and links -->
  <joint name="r_wrist_camera_infra2_joint" type="fixed">
    <origin rpy="0 0 0" xyz="0 -0.05 0"/>
    <parent link="r_wrist_camera_link"/>
    <child link="r_wrist_camera_infra2_frame"/>
  </joint>
  <link name="r_wrist_camera_infra2_frame"><inertial><origin xyz="0 0 0" rpy="0 0 0"/><mass value="0.001"/><inertia ixx="1e-6" ixy="0" ixz="0" iyy="1e-6" iyz="0" izz="1e-6"/></inertial></link>
  <joint name="r_wrist_camera_infra2_optical_joint" type="fixed">
    <origin rpy="-1.5707963267948966 0 -1.5707963267948966" xyz="0 0 0"/>
    <parent link="r_wrist_camera_infra2_frame"/>
    <child link="r_wrist_camera_infra2_optical_frame"/>
  </joint>
  <link name="r_wrist_camera_infra2_optical_frame"><inertial><origin xyz="0 0 0" rpy="0 0 0"/><mass value="0.001"/><inertia ixx="1e-6" ixy="0" ixz="0" iyy="1e-6" iyz="0" izz="1e-6"/></inertial></link>
  <!-- camera color joints and links -->
  <joint name="r_wrist_camera_color_joint" type="fixed">
    <origin rpy="0 0 0" xyz="0 0.015 0"/>
    <parent link="r_wrist_camera_link"/>
    <child link="r_wrist_camera_color_frame"/>
  </joint>
  <link name="r_wrist_camera_color_frame"><inertial><origin xyz="0 0 0" rpy="0 0 0"/><mass value="0.001"/><inertia ixx="1e-6" ixy="0" ixz="0" iyy="1e-6" iyz="0" izz="1e-6"/></inertial></link>
  <joint name="r_wrist_camera_color_optical_joint" type="fixed">
    <origin rpy="-1.5707963267948966 0 -1.5707963267948966" xyz="0 0 0"/>
    <parent link="r_wrist_camera_color_frame"/>
    <child link="r_wrist_camera_color_optical_frame"/>
  </joint>
  <link name="r_wrist_camera_color_optical_frame"><inertial><origin xyz="0 0 0" rpy="0 0 0"/><mass value="0.001"/><inertia ixx="1e-6" ixy="0" ixz="0" iyy="1e-6" iyz="0" izz="1e-6"/></inertial></link>
  <joint name="l_dex_hand_mount" type="fixed">
    <parent link="l_hand_link"/>
    <child link="l_dex_hand_base_link"/>
    <origin rpy="-1.5707963 0 3.14159" xyz="0 0 0"/>
  </joint>
  <link name="l_dex_hand_base_link">
    <inertial>
      <origin rpy="0 0 0" xyz="-0.0025264 -0.066047 -0.0019598"/>
      <mass value="0.14143"/>
      <inertia ixx="0.00012281" ixy="2.1711E-06" ixz="1.7709E-06" iyy="8.3832E-05" iyz="-1.6551E-06" izz="7.6663E-05"/>
    </inertial>
    <visual>
      <origin rpy="0 0 0" xyz="0 0 0"/>
      <geometry>
        <box size="0.001 0.001 0.001"/>
      </geometry>
    </visual>
    <collision>
      <origin rpy="1.57079 0 0" xyz="0 -0.0136 0"/>
      <geometry>
        <cylinder length="0.0278" radius="0.028"/>
      </geometry>
    </collision>
    <collision>
      <origin rpy="0 0 0" xyz="-0.0032 -0.038 0"/>
      <geometry>
        <box size="0.0391 0.0202 0.0574"/>
      </geometry>
    </collision>
    <collision>
      <origin rpy="0 0 0" xyz="-0.0032 -0.0682 0"/>
      <geometry>
        <box size="0.0391 0.04 0.0814"/>
      </geometry>
    </collision>
    <collision>
      <origin rpy="0 0 0" xyz="0 -0.1081 0"/>
      <geometry>
        <box size="0.0322 0.04 0.0814"/>
      </geometry>
    </collision>
    <collision>
      <origin rpy="0 0 0" xyz="-0.0016 -0.1340 -0.0309"/>
      <geometry>
        <box size="0.0125 0.0111 0.0089"/>
      </geometry>
    </collision>
    <collision>
      <origin rpy="0 0 0" xyz="-0.0016 -0.1340 -0.0118"/>
      <geometry>
        <box size="0.0125 0.0111 0.0089"/>
      </geometry>
    </collision>
    <collision>
      <origin rpy="0 0 0" xyz="-0.0016 -0.1340 0.0070"/>
      <geometry>
        <box size="0.0125 0.0111 0.0089"/>
      </geometry>
    </collision>
    <collision>
      <origin rpy="0 0 0" xyz="-0.0016 -0.1340 0.0262"/>
      <geometry>
        <box size="0.0125 0.0111 0.0089"/>
      </geometry>
    </collision>
  </link>
  <link name="l_dex_thumb_proximal_base">
    <inertial>
      <origin rpy="0 0 0" xyz="0.0048817 0.0009382 -0.00722"/>
      <mass value="0.0018869"/>
      <inertia ixx="5.816E-08" ixy="-1.4539E-08" ixz="-4.491E-09" iyy="7.9161E-08" iyz="-1.8727E-09" izz="6.7433E-08"/>
    </inertial>
    <visual>
      <origin rpy="0 0 0" xyz="0 0 0"/>
      <geometry>
        <box size="0.001 0.001 0.001"/>
      </geometry>
    </visual>
    <collision>
      <origin rpy="0 0 0" xyz="0 0 0"/>
      <geometry>
        <box size="0.001 0.001 0.001"/>
      </geometry>
    </collision>
  </link>
  <joint name="l_dex_thumb_proximal_yaw_joint" type="revolute">
    <origin rpy="1.5708 -1.5708 0" xyz="-0.01696 -0.0691 0.02045"/>
    <parent link="l_dex_hand_base_link"/>
    <child link="l_dex_thumb_proximal_base"/>
    <axis xyz="0 0 1"/>
    <limit effort="1" lower="0" upper="1.308" velocity="0.5"/>
  <dynamics damping="1.0" friction="0.1"/></joint>
  <link name="l_dex_thumb_proximal">
    <inertial>
      <origin rpy="0 0 0" xyz="0.021932 -0.012785 -0.0080386"/>
      <mass value="0.0066075"/>
      <inertia ixx="1.5686E-06" ixy="7.8296E-07" ixz="8.9143E-10" iyy="1.7353E-06" iyz="1.0191E-09" izz="2.786E-06"/>
    </inertial>
    <visual>
      <origin rpy="0 0 0" xyz="0 0 0"/>
      <geometry>
        <box size="0.001 0.001 0.001"/>
      </geometry>
    </visual>
    <collision>
      <origin rpy="0 0 0" xyz="0 0 0"/>
      <geometry>
        <box size="0.001 0.001 0.001"/>
      </geometry>
    </collision>
  </link>
  <joint name="l_dex_thumb_proximal_pitch_joint" type="revolute">
    <origin rpy="-1.5708 0 0.16939" xyz="0.0099867 0.0098242 -0.0089"/>
    <parent link="l_dex_thumb_proximal_base"/>
    <child link="l_dex_thumb_proximal"/>
    <axis xyz="0 0 -1"/>
    <limit effort="1" lower="0" upper="0.6" velocity="0.5"/>
  <dynamics damping="1.0" friction="0.1"/></joint>
  <link name="l_dex_thumb_intermediate">
    <inertial>
      <origin rpy="0 0 0" xyz="0.0095544 0.0016282 -0.0071997"/>
      <mass value="0.0037847"/>
      <inertia ixx="3.6981E-07" ixy="9.8581E-08" ixz="-4.7469E-12" iyy="3.2394E-07" iyz="-1.0939E-12" izz="4.6531E-07"/>
    </inertial>
    <visual>
      <origin rpy="0 0 0" xyz="0 0 0"/>
      <geometry>
        <box size="0.001 0.001 0.001"/>
      </geometry>
    </visual>
    <collision>
      <origin rpy="0 0 0" xyz="0 0 0"/>
      <geometry>
        <box size="0.001 0.001 0.001"/>
      </geometry>
    </collision>
  </link>
  <joint name="l_dex_thumb_intermediate_joint" type="revolute">
    <origin rpy="0 0 0" xyz="0.04407 -0.034553 -0.0008"/>
    <parent link="l_dex_thumb_proximal"/>
    <child link="l_dex_thumb_intermediate"/>
    <axis xyz="0 0 -1"/>
    <limit effort="1" lower="0" upper="0.8" velocity="0.5"/>
    <mimic joint="l_dex_thumb_proximal_pitch_joint" multiplier="1.334" offset="0"/>
  <dynamics damping="1.0" friction="0.1"/></joint>
  <link name="l_dex_thumb_distal">
    <inertial>
      <origin rpy="0 0 0" xyz="0.0092888 -0.0049529 -0.0060033"/>
      <mass value="0.0033441"/>
      <inertia ixx="1.3632E-07" ixy="5.6788E-08" ixz="-9.2764E-11" iyy="1.4052E-07" iyz="1.2283E-10" izz="2.0026E-07"/>
    </inertial>
    <visual>
      <origin rpy="0 0 0" xyz="0 0 0"/>
      <geometry>
        <box size="0.001 0.001 0.001"/>
      </geometry>
    </visual>
    <collision>
      <origin rpy="0 0 0" xyz="0 0 0"/>
      <geometry>
        <box size="0.001 0.001 0.001"/>
      </geometry>
    </collision>
  </link>
  <joint name="l_dex_thumb_distal_joint" type="revolute">
    <origin rpy="0 0 0" xyz="0.020248 -0.010156 -0.0012"/>
    <parent link="l_dex_thumb_intermediate"/>
    <child link="l_dex_thumb_distal"/>
    <axis xyz="0 0 -1"/>
    <limit effort="1" lower="0" upper="0.4" velocity="0.5"/>
    <mimic joint="l_dex_thumb_proximal_pitch_joint" multiplier="0.667" offset="0"/>
  <dynamics damping="1.0" friction="0.1"/></joint>
  <link name="l_dex_index_proximal">
    <inertial>
      <origin rpy="0 0 0" xyz="0.0012259 -0.011942 -0.0060001"/>
      <mass value="0.0042403"/>
      <inertia ixx="6.6232E-07" ixy="1.5775E-08" ixz="1.8515E-12" iyy="2.1146E-07" iyz="5.0828E-12" izz="6.9398E-07"/>
    </inertial>
    <visual>
      <origin rpy="0 0 0" xyz="0 0 0"/>
      <geometry>
        <box size="0.001 0.001 0.001"/>
      </geometry>
    </visual>
    <collision>
      <origin rpy="0 0 0" xyz="0 0 0"/>
      <geometry>
        <box size="0.001 0.001 0.001"/>
      </geometry>
    </collision>
  </link>
  <joint name="l_dex_index_proximal_joint" type="revolute">
    <origin rpy="-0.034907 0 0" xyz="0.00028533 -0.13653 0.032268"/>
    <parent link="l_dex_hand_base_link"/>
    <child link="l_dex_index_proximal"/>
    <axis xyz="0 0 -1"/>
    <limit effort="1" lower="0" upper="1.47" velocity="0.5"/>
  <dynamics damping="1.0" friction="0.1"/></joint>
  <link name="l_dex_index_intermediate">
    <inertial>
      <origin rpy="0 0 0" xyz="0.0019697 -0.019589 -0.005"/>
      <mass value="0.0045683"/>
      <inertia ixx="7.6111E-07" ixy="-8.7637E-08" ixz="-3.7751E-13" iyy="9.6076E-08" iyz="-9.9444E-13" izz="7.8179E-07"/>
    </inertial>
    <visual>
      <origin rpy="0 0 0" xyz="0 0 0"/>
      <geometry>
        <box size="0.001 0.001 0.001"/>
      </geometry>
    </visual>
    <collision>
      <origin rpy="0 0 0" xyz="0 0 0"/>
      <geometry>
        <box size="0.001 0.001 0.001"/>
      </geometry>
    </collision>
  </link>
  <joint name="l_dex_index_intermediate_joint" type="revolute">
    <origin rpy="0 0 0" xyz="-0.0026138 -0.032026 -0.001"/>
    <parent link="l_dex_index_proximal"/>
    <child link="l_dex_index_intermediate"/>
    <axis xyz="0 0 -1"/>
    <limit effort="1" lower="-0.04545" upper="1.56" velocity="0.5"/>
    <mimic joint="l_dex_index_proximal_joint" multiplier="1.06399" offset="-0.04545"/>
  <dynamics damping="1.0" friction="0.1"/></joint>
  <link name="l_dex_middle_proximal">
    <inertial>
      <origin rpy="0 0 0" xyz="0.001297 -0.011934 -0.0060001"/>
      <mass value="0.0042403"/>
      <inertia ixx="6.6211E-07" ixy="1.8461E-08" ixz="1.8002E-12" iyy="2.1167E-07" iyz="6.6808E-12" izz="6.9397E-07"/>
    </inertial>
    <visual>
      <origin rpy="0 0 0" xyz="0 0 0"/>
      <geometry>
        <box size="0.001 0.001 0.001"/>
      </geometry>
    </visual>
    <collision>
      <origin rpy="0 0 0" xyz="0 0 0"/>
      <geometry>
        <box size="0.001 0.001 0.001"/>
      </geometry>
    </collision>
  </link>
  <joint name="l_dex_middle_proximal_joint" type="revolute">
    <origin rpy="0 0 0" xyz="0.00028533 -0.1371 0.01295"/>
    <parent link="l_dex_hand_base_link"/>
    <child link="l_dex_middle_proximal"/>
    <axis xyz="0 0 -1"/>
    <limit effort="1" lower="0" upper="1.47" velocity="0.5"/>
  <dynamics damping="1.0" friction="0.1"/></joint>
  <link name="l_dex_middle_intermediate">
    <inertial>
      <origin rpy="0 0 0" xyz="0.001921 -0.020796 -0.005"/>
      <mass value="0.0050396"/>
      <inertia ixx="9.5822E-07" ixy="-1.1425E-07" ixz="-2.4791E-12" iyy="1.0646E-07" iyz="-5.9173E-12" izz="9.8384E-07"/>
    </inertial>
    <visual>
      <origin rpy="0 0 0" xyz="0 0 0"/>
      <geometry>
        <box size="0.001 0.001 0.001"/>
      </geometry>
    </visual>
    <collision>
      <origin rpy="0 0 0" xyz="0 0 0"/>
      <geometry>
        <box size="0.001 0.001 0.001"/>
      </geometry>
    </collision>
  </link>
  <joint name="l_dex_middle_intermediate_joint" type="revolute">
    <origin rpy="0 0 0" xyz="-0.0024229 -0.032041 -0.001"/>
    <parent link="l_dex_middle_proximal"/>
    <child link="l_dex_middle_intermediate"/>
    <axis xyz="0 0 -1"/>
    <limit effort="1" lower="-0.04545" upper="1.56" velocity="0.5"/>
    <mimic joint="l_dex_middle_proximal_joint" multiplier="1.06399" offset="-0.04545"/>
  <dynamics damping="1.0" friction="0.1"/></joint>
  <link name="l_dex_ring_proximal">
    <inertial>
      <origin rpy="0 0 0" xyz="0.001297 -0.011934 -0.0060002"/>
      <mass value="0.0042403"/>
      <inertia ixx="6.6211E-07" ixy="1.8461E-08" ixz="1.5793E-12" iyy="2.1167E-07" iyz="6.6868E-12" izz="6.9397E-07"/>
    </inertial>
    <visual>
      <origin rpy="0 0 0" xyz="0 0 0"/>
      <geometry>
        <box size="0.001 0.001 0.001"/>
      </geometry>
    </visual>
    <collision>
      <origin rpy="0 0 0" xyz="0 0 0"/>
      <geometry>
        <box size="0.001 0.001 0.001"/>
      </geometry>
    </collision>
  </link>
  <joint name="l_dex_ring_proximal_joint" type="revolute">
    <origin rpy="0.05236 0 0" xyz="0.00028533 -0.13691 -0.0062872"/>
    <parent link="l_dex_hand_base_link"/>
    <child link="l_dex_ring_proximal"/>
    <axis xyz="0 0 -1"/>
    <limit effort="1" lower="0" upper="1.47" velocity="0.5"/>
  <dynamics damping="1.0" friction="0.1"/></joint>
  <link name="l_dex_ring_intermediate">
    <inertial>
      <origin rpy="0 0 0" xyz="0.0021753 -0.019567 -0.005"/>
      <mass value="0.0045683"/>
      <inertia ixx="7.6286E-07" ixy="-8.0635E-08" ixz="-6.1562E-13" iyy="9.431E-08" iyz="-5.8619E-13" izz="7.8177E-07"/>
    </inertial>
    <visual>
      <origin rpy="0 0 0" xyz="0 0 0"/>
      <geometry>
        <box size="0.001 0.001 0.001"/>
      </geometry>
    </visual>
    <collision>
      <origin rpy="0 0 0" xyz="0 0 0"/>
      <geometry>
        <box size="0.001 0.001 0.001"/>
      </geometry>
    </collision>
  </link>
  <joint name="l_dex_ring_intermediate_joint" type="revolute">
    <origin rpy="0 0 0" xyz="-0.0024229 -0.032041 -0.001"/>
    <parent link="l_dex_ring_proximal"/>
    <child link="l_dex_ring_intermediate"/>
    <axis xyz="0 0 -1"/>
    <limit effort="1" lower="-0.04545" upper="1.56" velocity="0.5"/>
    <mimic joint="l_dex_ring_proximal_joint" multiplier="1.06399" offset="-0.04545"/>
  <dynamics damping="1.0" friction="0.1"/></joint>
  <link name="l_dex_pinky_proximal">
    <inertial>
      <origin rpy="0 0 0" xyz="0.001297 -0.011934 -0.0060001"/>
      <mass value="0.0042403"/>
      <inertia ixx="6.6211E-07" ixy="1.8461E-08" ixz="1.6907E-12" iyy="2.1167E-07" iyz="6.9334E-12" izz="6.9397E-07"/>
    </inertial>
    <visual>
      <origin rpy="0 0 0" xyz="0 0 0"/>
      <geometry>
        <box size="0.001 0.001 0.001"/>
      </geometry>
    </visual>
    <collision>
      <origin rpy="0 0 0" xyz="0 0 0"/>
      <geometry>
        <box size="0.001 0.001 0.001"/>
      </geometry>
    </collision>
  </link>
  <joint name="l_dex_pinky_proximal_joint" type="revolute">
    <origin rpy="0.10472 0 0" xyz="0.00028533 -0.13571 -0.025488"/>
    <parent link="l_dex_hand_base_link"/>
    <child link="l_dex_pinky_proximal"/>
    <axis xyz="0 0 -1"/>
    <limit effort="1" lower="0" upper="1.47" velocity="0.5"/>
  <dynamics damping="1.0" friction="0.1"/></joint>
  <link name="l_dex_pinky_intermediate">
    <inertial>
      <origin rpy="0 0 0" xyz="0.0024748 -0.016203 -0.0050031"/>
      <mass value="0.0035996"/>
      <inertia ixx="4.3913E-07" ixy="-4.1418E-08" ixz="3.7168E-11" iyy="7.0247E-08" iyz="-5.8613E-11" izz="4.4867E-07"/>
    </inertial>
    <visual>
      <origin rpy="0 0 0" xyz="0 0 0"/>
      <geometry>
        <box size="0.001 0.001 0.001"/>
      </geometry>
    </visual>
    <collision>
      <origin rpy="0 0 0" xyz="0 0 0"/>
      <geometry>
        <box size="0.001 0.001 0.001"/>
      </geometry>
    </collision>
  </link>
  <joint name="l_dex_pinky_intermediate_joint" type="revolute">
    <origin rpy="0 0 0" xyz="-0.0024229 -0.032041 -0.001"/>
    <parent link="l_dex_pinky_proximal"/>
    <child link="l_dex_pinky_intermediate"/>
    <axis xyz="0 0 -1"/>
    <limit effort="1" lower="-0.04545" upper="1.56" velocity="0.5"/>
    <mimic joint="l_dex_pinky_proximal_joint" multiplier="1.06399" offset="-0.04545"/>
  <dynamics damping="1.0" friction="0.1"/></joint>
  <link name="l_dex_thumb_tip"><inertial><origin xyz="0 0 0" rpy="0 0 0"/><mass value="0.001"/><inertia ixx="1e-6" ixy="0" ixz="0" iyy="1e-6" iyz="0" izz="1e-6"/></inertial></link>
  <joint name="l_dex_thumb_tip_joint" type="fixed">
    <origin rpy="0 0 0" xyz="0.0202 -0.0140 -0.006"/>
    <parent link="l_dex_thumb_distal"/>
    <child link="l_dex_thumb_tip"/>
  </joint>
  <link name="l_dex_index_tip"><inertial><origin xyz="0 0 0" rpy="0 0 0"/><mass value="0.001"/><inertia ixx="1e-6" ixy="0" ixz="0" iyy="1e-6" iyz="0" izz="1e-6"/></inertial></link>
  <joint name="l_dex_index_tip_joint" type="fixed">
    <origin rpy="0 0 0" xyz="-0.0008 -0.045 -0.005"/>
    <parent link="l_dex_index_intermediate"/>
    <child link="l_dex_index_tip"/>
  </joint>
  <link name="l_dex_middle_tip"><inertial><origin xyz="0 0 0" rpy="0 0 0"/><mass value="0.001"/><inertia ixx="1e-6" ixy="0" ixz="0" iyy="1e-6" iyz="0" izz="1e-6"/></inertial></link>
  <joint name="l_dex_middle_tip_joint" type="fixed">
    <origin rpy="0 0 0" xyz="-0.001 -0.048 -0.005"/>
    <parent link="l_dex_middle_intermediate"/>
    <child link="l_dex_middle_tip"/>
  </joint>
  <link name="l_dex_ring_tip"><inertial><origin xyz="0 0 0" rpy="0 0 0"/><mass value="0.001"/><inertia ixx="1e-6" ixy="0" ixz="0" iyy="1e-6" iyz="0" izz="1e-6"/></inertial></link>
  <joint name="l_dex_ring_tip_joint" type="fixed">
    <origin rpy="0 0 0" xyz="-0.0008 -0.045 -0.005"/>
    <parent link="l_dex_ring_intermediate"/>
    <child link="l_dex_ring_tip"/>
  </joint>
  <link name="l_dex_pinky_tip"><inertial><origin xyz="0 0 0" rpy="0 0 0"/><mass value="0.001"/><inertia ixx="1e-6" ixy="0" ixz="0" iyy="1e-6" iyz="0" izz="1e-6"/></inertial></link>
  <joint name="l_dex_pinky_tip_joint" type="fixed">
    <origin rpy="0 0 0" xyz="-0.0008 -0.037 -0.005"/>
    <parent link="l_dex_pinky_intermediate"/>
    <child link="l_dex_pinky_tip"/>
  </joint>
  <joint name="r_dex_hand_mount" type="fixed">
    <parent link="r_hand"/>
    <child link="r_dex_hand_base_link"/>
    <origin rpy="-1.5707963 0 3.14159" xyz="0 0 0"/>
  </joint>
  <link name="r_dex_hand_base_link">
    <inertial>
      <origin rpy="0 0 0" xyz="-0.0025264 -0.066047 -0.0019598"/>
      <mass value="0.14143"/>
      <inertia ixx="0.00012281" ixy="2.1711E-06" ixz="1.7709E-06" iyy="8.3832E-05" iyz="-1.6551E-06" izz="7.6663E-05"/>
    </inertial>
    <visual>
      <origin rpy="0 0 0" xyz="0 0 0"/>
      <geometry>
        <box size="0.001 0.001 0.001"/>
      </geometry>
    </visual>
    <collision>
      <origin rpy="1.57079 0 0" xyz="0 -0.0136 0"/>
      <geometry>
        <cylinder length="0.0278" radius="0.028"/>
      </geometry>
    </collision>
    <collision>
      <origin rpy="0 0 0" xyz="-0.0032 -0.038 0"/>
      <geometry>
        <box size="0.0391 0.0202 0.0574"/>
      </geometry>
    </collision>
    <collision>
      <origin rpy="0 0 0" xyz="-0.0032 -0.0682 0"/>
      <geometry>
        <box size="0.0391 0.04 0.0814"/>
      </geometry>
    </collision>
    <collision>
      <origin rpy="0 0 0" xyz="0 -0.1081 0"/>
      <geometry>
        <box size="0.0322 0.04 0.0814"/>
      </geometry>
    </collision>
    <collision>
      <origin rpy="0 0 0" xyz="-0.0016 -0.1340 -0.0309"/>
      <geometry>
        <box size="0.0125 0.0111 0.0089"/>
      </geometry>
    </collision>
    <collision>
      <origin rpy="0 0 0" xyz="-0.0016 -0.1340 -0.0118"/>
      <geometry>
        <box size="0.0125 0.0111 0.0089"/>
      </geometry>
    </collision>
    <collision>
      <origin rpy="0 0 0" xyz="-0.0016 -0.1340 0.0070"/>
      <geometry>
        <box size="0.0125 0.0111 0.0089"/>
      </geometry>
    </collision>
    <collision>
      <origin rpy="0 0 0" xyz="-0.0016 -0.1340 0.0262"/>
      <geometry>
        <box size="0.0125 0.0111 0.0089"/>
      </geometry>
    </collision>
  </link>
  <link name="r_dex_thumb_proximal_base">
    <inertial>
      <origin rpy="0 0 0" xyz="0.0048817 0.0009382 -0.00722"/>
      <mass value="0.0018869"/>
      <inertia ixx="5.816E-08" ixy="-1.4539E-08" ixz="-4.491E-09" iyy="7.9161E-08" iyz="-1.8727E-09" izz="6.7433E-08"/>
    </inertial>
    <visual>
      <origin rpy="0 0 0" xyz="0 0 0"/>
      <geometry>
        <box size="0.001 0.001 0.001"/>
      </geometry>
    </visual>
    <collision>
      <origin rpy="0 0 0" xyz="0 0 0"/>
      <geometry>
        <box size="0.001 0.001 0.001"/>
      </geometry>
    </collision>
  </link>
  <joint name="r_dex_thumb_proximal_yaw_joint" type="revolute">
    <origin rpy="1.5708 -1.5708 0" xyz="-0.01696 -0.0691 0.02045"/>
    <parent link="r_dex_hand_base_link"/>
    <child link="r_dex_thumb_proximal_base"/>
    <axis xyz="0 0 1"/>
    <limit effort="1" lower="0" upper="1.308" velocity="0.5"/>
  <dynamics damping="1.0" friction="0.1"/></joint>
  <link name="r_dex_thumb_proximal">
    <inertial>
      <origin rpy="0 0 0" xyz="0.021932 -0.012785 -0.0080386"/>
      <mass value="0.0066075"/>
      <inertia ixx="1.5686E-06" ixy="7.8296E-07" ixz="8.9143E-10" iyy="1.7353E-06" iyz="1.0191E-09" izz="2.786E-06"/>
    </inertial>
    <visual>
      <origin rpy="0 0 0" xyz="0 0 0"/>
      <geometry>
        <box size="0.001 0.001 0.001"/>
      </geometry>
    </visual>
    <collision>
      <origin rpy="0 0 0" xyz="0 0 0"/>
      <geometry>
        <box size="0.001 0.001 0.001"/>
      </geometry>
    </collision>
  </link>
  <joint name="r_dex_thumb_proximal_pitch_joint" type="revolute">
    <origin rpy="-1.5708 0 0.16939" xyz="0.0099867 0.0098242 -0.0089"/>
    <parent link="r_dex_thumb_proximal_base"/>
    <child link="r_dex_thumb_proximal"/>
    <axis xyz="0 0 -1"/>
    <limit effort="1" lower="0" upper="0.6" velocity="0.5"/>
  <dynamics damping="1.0" friction="0.1"/></joint>
  <link name="r_dex_thumb_intermediate">
    <inertial>
      <origin rpy="0 0 0" xyz="0.0095544 0.0016282 -0.0071997"/>
      <mass value="0.0037847"/>
      <inertia ixx="3.6981E-07" ixy="9.8581E-08" ixz="-4.7469E-12" iyy="3.2394E-07" iyz="-1.0939E-12" izz="4.6531E-07"/>
    </inertial>
    <visual>
      <origin rpy="0 0 0" xyz="0 0 0"/>
      <geometry>
        <box size="0.001 0.001 0.001"/>
      </geometry>
    </visual>
    <collision>
      <origin rpy="0 0 0" xyz="0 0 0"/>
      <geometry>
        <box size="0.001 0.001 0.001"/>
      </geometry>
    </collision>
  </link>
  <joint name="r_dex_thumb_intermediate_joint" type="revolute">
    <origin rpy="0 0 0" xyz="0.04407 -0.034553 -0.0008"/>
    <parent link="r_dex_thumb_proximal"/>
    <child link="r_dex_thumb_intermediate"/>
    <axis xyz="0 0 -1"/>
    <limit effort="1" lower="0" upper="0.8" velocity="0.5"/>
    <mimic joint="r_dex_thumb_proximal_pitch_joint" multiplier="1.334" offset="0"/>
  <dynamics damping="1.0" friction="0.1"/></joint>
  <link name="r_dex_thumb_distal">
    <inertial>
      <origin rpy="0 0 0" xyz="0.0092888 -0.0049529 -0.0060033"/>
      <mass value="0.0033441"/>
      <inertia ixx="1.3632E-07" ixy="5.6788E-08" ixz="-9.2764E-11" iyy="1.4052E-07" iyz="1.2283E-10" izz="2.0026E-07"/>
    </inertial>
    <visual>
      <origin rpy="0 0 0" xyz="0 0 0"/>
      <geometry>
        <box size="0.001 0.001 0.001"/>
      </geometry>
    </visual>
    <collision>
      <origin rpy="0 0 0" xyz="0 0 0"/>
      <geometry>
        <box size="0.001 0.001 0.001"/>
      </geometry>
    </collision>
  </link>
  <joint name="r_dex_thumb_distal_joint" type="revolute">
    <origin rpy="0 0 0" xyz="0.020248 -0.010156 -0.0012"/>
    <parent link="r_dex_thumb_intermediate"/>
    <child link="r_dex_thumb_distal"/>
    <axis xyz="0 0 -1"/>
    <limit effort="1" lower="0" upper="0.4" velocity="0.5"/>
    <mimic joint="r_dex_thumb_proximal_pitch_joint" multiplier="0.667" offset="0"/>
  <dynamics damping="1.0" friction="0.1"/></joint>
  <link name="r_dex_index_proximal">
    <inertial>
      <origin rpy="0 0 0" xyz="0.0012259 -0.011942 -0.0060001"/>
      <mass value="0.0042403"/>
      <inertia ixx="6.6232E-07" ixy="1.5775E-08" ixz="1.8515E-12" iyy="2.1146E-07" iyz="5.0828E-12" izz="6.9398E-07"/>
    </inertial>
    <visual>
      <origin rpy="0 0 0" xyz="0 0 0"/>
      <geometry>
        <box size="0.001 0.001 0.001"/>
      </geometry>
    </visual>
    <collision>
      <origin rpy="0 0 0" xyz="0 0 0"/>
      <geometry>
        <box size="0.001 0.001 0.001"/>
      </geometry>
    </collision>
  </link>
  <joint name="r_dex_index_proximal_joint" type="revolute">
    <origin rpy="-0.034907 0 0" xyz="0.00028533 -0.13653 0.032268"/>
    <parent link="r_dex_hand_base_link"/>
    <child link="r_dex_index_proximal"/>
    <axis xyz="0 0 -1"/>
    <limit effort="1" lower="0" upper="1.47" velocity="0.5"/>
  <dynamics damping="1.0" friction="0.1"/></joint>
  <link name="r_dex_index_intermediate">
    <inertial>
      <origin rpy="0 0 0" xyz="0.0019697 -0.019589 -0.005"/>
      <mass value="0.0045683"/>
      <inertia ixx="7.6111E-07" ixy="-8.7637E-08" ixz="-3.7751E-13" iyy="9.6076E-08" iyz="-9.9444E-13" izz="7.8179E-07"/>
    </inertial>
    <visual>
      <origin rpy="0 0 0" xyz="0 0 0"/>
      <geometry>
        <box size="0.001 0.001 0.001"/>
      </geometry>
    </visual>
    <collision>
      <origin rpy="0 0 0" xyz="0 0 0"/>
      <geometry>
        <box size="0.001 0.001 0.001"/>
      </geometry>
    </collision>
  </link>
  <joint name="r_dex_index_intermediate_joint" type="revolute">
    <origin rpy="0 0 0" xyz="-0.0026138 -0.032026 -0.001"/>
    <parent link="r_dex_index_proximal"/>
    <child link="r_dex_index_intermediate"/>
    <axis xyz="0 0 -1"/>
    <limit effort="1" lower="-0.04545" upper="1.56" velocity="0.5"/>
    <mimic joint="r_dex_index_proximal_joint" multiplier="1.06399" offset="-0.04545"/>
  <dynamics damping="1.0" friction="0.1"/></joint>
  <link name="r_dex_middle_proximal">
    <inertial>
      <origin rpy="0 0 0" xyz="0.001297 -0.011934 -0.0060001"/>
      <mass value="0.0042403"/>
      <inertia ixx="6.6211E-07" ixy="1.8461E-08" ixz="1.8002E-12" iyy="2.1167E-07" iyz="6.6808E-12" izz="6.9397E-07"/>
    </inertial>
    <visual>
      <origin rpy="0 0 0" xyz="0 0 0"/>
      <geometry>
        <box size="0.001 0.001 0.001"/>
      </geometry>
    </visual>
    <collision>
      <origin rpy="0 0 0" xyz="0 0 0"/>
      <geometry>
        <box size="0.001 0.001 0.001"/>
      </geometry>
    </collision>
  </link>
  <joint name="r_dex_middle_proximal_joint" type="revolute">
    <origin rpy="0 0 0" xyz="0.00028533 -0.1371 0.01295"/>
    <parent link="r_dex_hand_base_link"/>
    <child link="r_dex_middle_proximal"/>
    <axis xyz="0 0 -1"/>
    <limit effort="1" lower="0" upper="1.47" velocity="0.5"/>
  <dynamics damping="1.0" friction="0.1"/></joint>
  <link name="r_dex_middle_intermediate">
    <inertial>
      <origin rpy="0 0 0" xyz="0.001921 -0.020796 -0.005"/>
      <mass value="0.0050396"/>
      <inertia ixx="9.5822E-07" ixy="-1.1425E-07" ixz="-2.4791E-12" iyy="1.0646E-07" iyz="-5.9173E-12" izz="9.8384E-07"/>
    </inertial>
    <visual>
      <origin rpy="0 0 0" xyz="0 0 0"/>
      <geometry>
        <box size="0.001 0.001 0.001"/>
      </geometry>
    </visual>
    <collision>
      <origin rpy="0 0 0" xyz="0 0 0"/>
      <geometry>
        <box size="0.001 0.001 0.001"/>
      </geometry>
    </collision>
  </link>
  <joint name="r_dex_middle_intermediate_joint" type="revolute">
    <origin rpy="0 0 0" xyz="-0.0024229 -0.032041 -0.001"/>
    <parent link="r_dex_middle_proximal"/>
    <child link="r_dex_middle_intermediate"/>
    <axis xyz="0 0 -1"/>
    <limit effort="1" lower="-0.04545" upper="1.56" velocity="0.5"/>
    <mimic joint="r_dex_middle_proximal_joint" multiplier="1.06399" offset="-0.04545"/>
  <dynamics damping="1.0" friction="0.1"/></joint>
  <link name="r_dex_ring_proximal">
    <inertial>
      <origin rpy="0 0 0" xyz="0.001297 -0.011934 -0.0060002"/>
      <mass value="0.0042403"/>
      <inertia ixx="6.6211E-07" ixy="1.8461E-08" ixz="1.5793E-12" iyy="2.1167E-07" iyz="6.6868E-12" izz="6.9397E-07"/>
    </inertial>
    <visual>
      <origin rpy="0 0 0" xyz="0 0 0"/>
      <geometry>
        <box size="0.001 0.001 0.001"/>
      </geometry>
    </visual>
    <collision>
      <origin rpy="0 0 0" xyz="0 0 0"/>
      <geometry>
        <box size="0.001 0.001 0.001"/>
      </geometry>
    </collision>
  </link>
  <joint name="r_dex_ring_proximal_joint" type="revolute">
    <origin rpy="0.05236 0 0" xyz="0.00028533 -0.13691 -0.0062872"/>
    <parent link="r_dex_hand_base_link"/>
    <child link="r_dex_ring_proximal"/>
    <axis xyz="0 0 -1"/>
    <limit effort="1" lower="0" upper="1.47" velocity="0.5"/>
  <dynamics damping="1.0" friction="0.1"/></joint>
  <link name="r_dex_ring_intermediate">
    <inertial>
      <origin rpy="0 0 0" xyz="0.0021753 -0.019567 -0.005"/>
      <mass value="0.0045683"/>
      <inertia ixx="7.6286E-07" ixy="-8.0635E-08" ixz="-6.1562E-13" iyy="9.431E-08" iyz="-5.8619E-13" izz="7.8177E-07"/>
    </inertial>
    <visual>
      <origin rpy="0 0 0" xyz="0 0 0"/>
      <geometry>
        <box size="0.001 0.001 0.001"/>
      </geometry>
    </visual>
    <collision>
      <origin rpy="0 0 0" xyz="0 0 0"/>
      <geometry>
        <box size="0.001 0.001 0.001"/>
      </geometry>
    </collision>
  </link>
  <joint name="r_dex_ring_intermediate_joint" type="revolute">
    <origin rpy="0 0 0" xyz="-0.0024229 -0.032041 -0.001"/>
    <parent link="r_dex_ring_proximal"/>
    <child link="r_dex_ring_intermediate"/>
    <axis xyz="0 0 -1"/>
    <limit effort="1" lower="-0.04545" upper="1.56" velocity="0.5"/>
    <mimic joint="r_dex_ring_proximal_joint" multiplier="1.06399" offset="-0.04545"/>
  <dynamics damping="1.0" friction="0.1"/></joint>
  <link name="r_dex_pinky_proximal">
    <inertial>
      <origin rpy="0 0 0" xyz="0.001297 -0.011934 -0.0060001"/>
      <mass value="0.0042403"/>
      <inertia ixx="6.6211E-07" ixy="1.8461E-08" ixz="1.6907E-12" iyy="2.1167E-07" iyz="6.9334E-12" izz="6.9397E-07"/>
    </inertial>
    <visual>
      <origin rpy="0 0 0" xyz="0 0 0"/>
      <geometry>
        <box size="0.001 0.001 0.001"/>
      </geometry>
    </visual>
    <collision>
      <origin rpy="0 0 0" xyz="0 0 0"/>
      <geometry>
        <box size="0.001 0.001 0.001"/>
      </geometry>
    </collision>
  </link>
  <joint name="r_dex_pinky_proximal_joint" type="revolute">
    <origin rpy="0.10472 0 0" xyz="0.00028533 -0.13571 -0.025488"/>
    <parent link="r_dex_hand_base_link"/>
    <child link="r_dex_pinky_proximal"/>
    <axis xyz="0 0 -1"/>
    <limit effort="1" lower="0" upper="1.47" velocity="0.5"/>
  <dynamics damping="1.0" friction="0.1"/></joint>
  <link name="r_dex_pinky_intermediate">
    <inertial>
      <origin rpy="0 0 0" xyz="0.0024748 -0.016203 -0.0050031"/>
      <mass value="0.0035996"/>
      <inertia ixx="4.3913E-07" ixy="-4.1418E-08" ixz="3.7168E-11" iyy="7.0247E-08" iyz="-5.8613E-11" izz="4.4867E-07"/>
    </inertial>
    <visual>
      <origin rpy="0 0 0" xyz="0 0 0"/>
      <geometry>
        <box size="0.001 0.001 0.001"/>
      </geometry>
    </visual>
    <collision>
      <origin rpy="0 0 0" xyz="0 0 0"/>
      <geometry>
        <box size="0.001 0.001 0.001"/>
      </geometry>
    </collision>
  </link>
  <joint name="r_dex_pinky_intermediate_joint" type="revolute">
    <origin rpy="0 0 0" xyz="-0.0024229 -0.032041 -0.001"/>
    <parent link="r_dex_pinky_proximal"/>
    <child link="r_dex_pinky_intermediate"/>
    <axis xyz="0 0 -1"/>
    <limit effort="1" lower="-0.04545" upper="1.56" velocity="0.5"/>
    <mimic joint="r_dex_pinky_proximal_joint" multiplier="1.06399" offset="-0.04545"/>
  <dynamics damping="1.0" friction="0.1"/></joint>
  <link name="r_dex_thumb_tip"><inertial><origin xyz="0 0 0" rpy="0 0 0"/><mass value="0.001"/><inertia ixx="1e-6" ixy="0" ixz="0" iyy="1e-6" iyz="0" izz="1e-6"/></inertial></link>
  <joint name="r_dex_thumb_tip_joint" type="fixed">
    <origin rpy="0 0 0" xyz="0.0202 -0.0140 -0.006"/>
    <parent link="r_dex_thumb_distal"/>
    <child link="r_dex_thumb_tip"/>
  </joint>
  <link name="r_dex_index_tip"><inertial><origin xyz="0 0 0" rpy="0 0 0"/><mass value="0.001"/><inertia ixx="1e-6" ixy="0" ixz="0" iyy="1e-6" iyz="0" izz="1e-6"/></inertial></link>
  <joint name="r_dex_index_tip_joint" type="fixed">
    <origin rpy="0 0 0" xyz="-0.0008 -0.045 -0.005"/>
    <parent link="r_dex_index_intermediate"/>
    <child link="r_dex_index_tip"/>
  </joint>
  <link name="r_dex_middle_tip"><inertial><origin xyz="0 0 0" rpy="0 0 0"/><mass value="0.001"/><inertia ixx="1e-6" ixy="0" ixz="0" iyy="1e-6" iyz="0" izz="1e-6"/></inertial></link>
  <joint name="r_dex_middle_tip_joint" type="fixed">
    <origin rpy="0 0 0" xyz="-0.001 -0.048 -0.005"/>
    <parent link="r_dex_middle_intermediate"/>
    <child link="r_dex_middle_tip"/>
  </joint>
  <link name="r_dex_ring_tip"><inertial><origin xyz="0 0 0" rpy="0 0 0"/><mass value="0.001"/><inertia ixx="1e-6" ixy="0" ixz="0" iyy="1e-6" iyz="0" izz="1e-6"/></inertial></link>
  <joint name="r_dex_ring_tip_joint" type="fixed">
    <origin rpy="0 0 0" xyz="-0.0008 -0.045 -0.005"/>
    <parent link="r_dex_ring_intermediate"/>
    <child link="r_dex_ring_tip"/>
  </joint>
  <link name="r_dex_pinky_tip"><inertial><origin xyz="0 0 0" rpy="0 0 0"/><mass value="0.001"/><inertia ixx="1e-6" ixy="0" ixz="0" iyy="1e-6" iyz="0" izz="1e-6"/></inertial></link>
  <joint name="r_dex_pinky_tip_joint" type="fixed">
    <origin rpy="0 0 0" xyz="-0.0008 -0.037 -0.005"/>
    <parent link="r_dex_pinky_intermediate"/>
    <child link="r_dex_pinky_tip"/>
  </joint>
</robot>
